<?xml version="1.0" ?>
<!-- =================================================================================== -->
<!-- |    This document was autogenerated by xacro from robot.xacro                    | -->
<!-- |    EDITING THIS FILE BY HAND IS NOT RECOMMENDED                                 | -->
<!-- =================================================================================== -->
<!-- http://wiki.ros.org/xacro -->
<robot name="commissioning_robot">
  <!-- <material name="red">
    <color rgba="1.0 0.0 0.0 1"/>
  </material>
  <material name="green">
    <color rgba="0.0 1.0 0.0 1"/>
  </material>
  <material name="blue">
    <color rgba="0.0 0.0 1.0 1"/>
  </material> -->
  <material name="red">
    <color rgba="0.9 1 1 1"/>
  </material>
  <material name="green">
    <color rgba="1 0.9 1 1"/>
  </material>
  <material name="blue">
    <color rgba="1 1 0.9 1"/>
  </material>
  <!-- 
  設計方針としてSTLメッシュに対してリンクの原点系は変更しない
  ジョイントの原点位置を変更することでモデルの位置を調整する
  こうすることによってCAD上のジオメトリで定義されているデータムと簡単に整合性を取ることができる
  →無数にある全体アセンブリのデータムからパーツ間距離計測が容易にできる
 -->
  <link name="base_link"/>
  <gazebo>
    <plugin filename="libgazebo_ros_control.so" name="gazebo_ros_control">
      <robotNamespace>/commissioning_robot</robotNamespace>
      <!-- <robotSimType>gazebo_ros_control/DefaultRobotHWSim</robotSimType> -->
      <!-- <legacyModeNS>true</legacyModeNS> -->
    </plugin>
  </gazebo>
  <!-- definition of links -->
  <link name="drive_base_link">
    <visual>
      <geometry>
        <mesh filename="package://commissioning_robot/stl/03c-all-base-drive.stl"/>
      </geometry>
      <origin rpy="0 0 3.141592653589793" xyz="0 0 0"/>
      <material name="red"/>
    </visual>
    <inertial>
      <origin rpy="1.5707963267948966 0 0" xyz="0 0 0"/>
      <mass value="5.7106171"/>
      <inertia ixx="0.37539268" ixy="0.0" ixz="-0.0004602346" iyx="0.0" iyy="0.54083174" iyz="-5.0803986e-05" izx="-0.0004602346" izy="-5.0803986e-05" izz="0.17633812"/>
    </inertial>
    <collision>
      <origin rpy="0 0 3.141592653589793" xyz="0 0 0"/>
      <geometry>
        <mesh filename="package://commissioning_robot/stl/03c-all-base-drive.stl"/>
      </geometry>
    </collision>
  </link>
  <gazebo reference="drive_base_link">
    <material>Gazebo/Grey</material>
    <mu1>0</mu1>
    <mu2>0</mu2>
    <kp>10000000000000.0</kp>
    <kd>1</kd>
    <dampingFactor>0</dampingFactor>
    <!-- <minDepth>0.001</minDepth> -->
    <!-- <maxVel>0.01</maxVel> -->
    <!-- <turnGravityOff>true</turnGravityOff> -->
  </gazebo>
  <link name="lift1_link">
    <visual>
      <geometry>
        <mesh filename="package://commissioning_robot/stl/asm-03c-ud-drive-unit2.stl"/>
      </geometry>
      <origin rpy="0 0 -1.5707963267948966" xyz="0 0 0"/>
      <material name="blue"/>
    </visual>
    <inertial>
      <origin rpy="1.5707963267948966 0 0" xyz="0 0 0"/>
      <mass value="1.1426868"/>
      <inertia ixx="0.028638897" ixy="0.00041858462" ixz="0.00063414972" iyx="0.00041858462" iyy="0.0072862805" iyz="0.0024968875" izx="0.00063414972" izy="0.0024968875" izz="0.027182379"/>
    </inertial>
    <collision>
      <origin rpy="0 0 -1.5707963267948966" xyz="0 0 0"/>
      <geometry>
        <box size="0 0 0"/>
      </geometry>
    </collision>
  </link>
  <gazebo reference="lift1_link">
    <material>Gazebo/Grey</material>
    <mu1>0</mu1>
    <mu2>0</mu2>
    <kp>10000000000000.0</kp>
    <kd>0.01</kd>
    <dampingFactor>0.01</dampingFactor>
    <!-- <minDepth>0.001</minDepth> -->
    <!-- <maxVel>0.01</maxVel> -->
    <!-- <turnGravityOff>true</turnGravityOff> -->
  </gazebo>
  <link name="lift2_link">
    <visual>
      <geometry>
        <mesh filename="package://commissioning_robot/stl/asm-03c-ud-drive-unit1.stl"/>
      </geometry>
      <origin rpy="0 0 -1.5707963267948966" xyz="0 0 0"/>
      <material name="blue"/>
    </visual>
    <inertial>
      <origin rpy="1.5707963267948966 0 0" xyz="0 0 0"/>
      <mass value="1.1440346"/>
      <inertia ixx="0.028643666" ixy="0.00041966804" ixz="-0.00063324236" iyx="0.00041966804" iyy="0.0072885831" iyz="-0.0024972389" izx="-0.00063324236" izy="-0.0024972389" izz="0.027186401"/>
    </inertial>
    <collision>
      <origin rpy="0 0 -1.5707963267948966" xyz="0 0 0"/>
      <geometry>
        <box size="0 0 0"/>
      </geometry>
    </collision>
  </link>
  <gazebo reference="lift2_link">
    <material>Gazebo/Grey</material>
    <mu1>0</mu1>
    <mu2>0</mu2>
    <kp>10000000000000.0</kp>
    <kd>0.01</kd>
    <dampingFactor>0.01</dampingFactor>
    <!-- <minDepth>0.001</minDepth> -->
    <!-- <maxVel>0.01</maxVel> -->
    <!-- <turnGravityOff>true</turnGravityOff> -->
  </gazebo>
  <link name="lift3_link">
    <visual>
      <geometry>
        <mesh filename="package://commissioning_robot/stl/asm-03c-ud-drive-unit2.stl"/>
      </geometry>
      <origin rpy="0 0 1.5707963267948966" xyz="0 0 0"/>
      <material name="blue"/>
    </visual>
    <inertial>
      <origin rpy="1.5707963267948966 0 0" xyz="0 0 0"/>
      <mass value="1.1426868"/>
      <inertia ixx="0.028638897" ixy="0.00041858462" ixz="0.00063414972" iyx="0.00041858462" iyy="0.0072862805" iyz="0.0024968875" izx="0.00063414972" izy="0.0024968875" izz="0.027182379"/>
    </inertial>
    <collision>
      <origin rpy="0 0 1.5707963267948966" xyz="0 0 0"/>
      <geometry>
        <box size="0 0 0"/>
      </geometry>
    </collision>
  </link>
  <gazebo reference="lift3_link">
    <material>Gazebo/Grey</material>
    <mu1>0</mu1>
    <mu2>0</mu2>
    <kp>10000000000000.0</kp>
    <kd>0.01</kd>
    <dampingFactor>0.01</dampingFactor>
    <!-- <minDepth>0.001</minDepth> -->
    <!-- <maxVel>0.01</maxVel> -->
    <!-- <turnGravityOff>true</turnGravityOff> -->
  </gazebo>
  <link name="lift4_link">
    <visual>
      <geometry>
        <mesh filename="package://commissioning_robot/stl/asm-03c-ud-drive-unit1.stl"/>
      </geometry>
      <origin rpy="0 0 1.5707963267948966" xyz="0 0 0"/>
      <material name="blue"/>
    </visual>
    <inertial>
      <origin rpy="1.5707963267948966 0 0" xyz="0 0 0"/>
      <mass value="1.1440346"/>
      <inertia ixx="0.028643666" ixy="0.00041966804" ixz="-0.00063324236" iyx="0.00041966804" iyy="0.0072885831" iyz="-0.0024972389" izx="-0.00063324236" izy="-0.0024972389" izz="0.027186401"/>
    </inertial>
    <collision>
      <origin rpy="0 0 1.5707963267948966" xyz="0 0 0"/>
      <geometry>
        <box size="0 0 0"/>
      </geometry>
    </collision>
  </link>
  <gazebo reference="lift4_link">
    <material>Gazebo/Grey</material>
    <mu1>0</mu1>
    <mu2>0</mu2>
    <kp>10000000000000.0</kp>
    <kd>0.01</kd>
    <dampingFactor>0.01</dampingFactor>
    <!-- <minDepth>0.001</minDepth> -->
    <!-- <maxVel>0.01</maxVel> -->
    <!-- <turnGravityOff>true</turnGravityOff> -->
  </gazebo>
  <link name="mechanum1_link">
    <visual>
      <geometry>
        <mesh filename="package://commissioning_robot/stl/03-asm-mechanum-r.stl"/>
      </geometry>
      <origin rpy="0.3490658503988659 0 3.141592653589793" xyz="0 0 0"/>
      <material name="blue"/>
    </visual>
    <inertial>
      <origin rpy="0 0 0" xyz="0 0 0"/>
      <mass value="0.2283143"/>
      <inertia ixx="0.00013964271" ixy="3.410723e-07" ixz="-4.0592855e-08" iyx="3.410723e-07" iyy="0.00014237371" iyz="-1.5000035e-08" izx="-4.0592855e-08" izy="1.5000035e-08" izz="0.00014228702"/>
    </inertial>
    <collision>
      <origin rpy="0.3490658503988659 0 3.141592653589793" xyz="0 0 0"/>
      <geometry>
        <box size="0 0 0"/>
      </geometry>
    </collision>
  </link>
  <gazebo reference="mechanum1_link">
    <material>Gazebo/Grey</material>
    <mu1>1</mu1>
    <mu2>1</mu2>
    <kp>20000000000.0</kp>
    <kd>0.01</kd>
    <dampingFactor>0.01</dampingFactor>
    <!-- <minDepth>0.001</minDepth> -->
    <!-- <maxVel>0.01</maxVel> -->
    <!-- <turnGravityOff>true</turnGravityOff> -->
  </gazebo>
  <link name="mechanum1_link_barrel1">
    <visual>
      <geometry>
        <mesh filename="package://commissioning_robot/stl/ots-barrel-display_s.stl"/>
      </geometry>
      <origin rpy="0 0 0" xyz="0 0 0"/>
      <material name="blue"/>
    </visual>
    <inertial>
      <origin rpy="0 0 0" xyz="0 0 0"/>
      <mass value="0.020168905"/>
      <inertia ixx="9.115874e-07" ixy="0.0" ixz="0.0" iyx="0.0" iyy="3.5976895e-06" iyz="0.0" izx="0.0" izy="0.0" izz="3.5976895e-06"/>
    </inertial>
    <collision>
      <origin rpy="0 0 0" xyz="0 0 0"/>
      <geometry>
        <mesh filename="package://commissioning_robot/stl/ots-barrel-display_s.stl"/>
      </geometry>
    </collision>
  </link>
  <!-- <xacro:INSERT_GAZEBO_PHYSICS_UNIT  suffix="${suffix}" mu1="${1}" mu2="${1}" kp="${2e8}" kd="${0.1}" df="${0.03}" color="Gazebo/GreyGradientSky"/> -->
  <!-- <xacro:INSERT_GAZEBO_PHYSICS_UNIT  suffix="${suffix}" mu1="${1}" mu2="${1}" kp="${1}" kd="${1}" df="${0}" color="Gazebo/GreyGradientSky"/> -->
  <gazebo reference="mechanum1_link_barrel1">
    <material>Gazebo/GreyGradientSky</material>
    <dampingFactor>0.01</dampingFactor>
  </gazebo>
  <joint name="mechanum1_link_barrel1_joint" type="continuous">
    <parent link="mechanum1_link"/>
    <child link="mechanum1_link_barrel1"/>
    <origin rpy="0.0 0.7853981633974483 0.0" xyz="0 0.04029 0.0"/>
    <axis xyz="1 0 0"/>
    <!-- <dynamics damping="1e-4"/> -->
    <!-- <limit effort="10000" velocity="10000"/> -->
    <!-- <safety_controller k_velocity="10" k_position="15" soft_lower_limit="-2.0" soft_upper_limit="0.5" /> -->
    <!-- <safety_controller k_velocity="10" k_position="15" /> -->
    <!-- <dynamics friction="10"/> -->
  </joint>
  <transmission name="mechanum1_link_barrel1_trans">
    <type>transmission_interface/SimpleTransmission</type>
    <joint name="mechanum1_link_barrel1_joint">
      <hardwareInterface>hardware_interface/EffortJointInterface</hardwareInterface>
    </joint>
    <actuator name="mechanum1_link_barrel1_motor">
      <hardwareInterface>hardware_interface/EffortJointInterface</hardwareInterface>
      <mechanismReduction>1</mechanismReduction>
    </actuator>
  </transmission>
  <link name="mechanum1_link_barrel2">
    <visual>
      <geometry>
        <mesh filename="package://commissioning_robot/stl/ots-barrel-display_s.stl"/>
      </geometry>
      <origin rpy="0 0 0" xyz="0 0 0"/>
      <material name="blue"/>
    </visual>
    <inertial>
      <origin rpy="0 0 0" xyz="0 0 0"/>
      <mass value="0.020168905"/>
      <inertia ixx="9.115874e-07" ixy="0.0" ixz="0.0" iyx="0.0" iyy="3.5976895e-06" iyz="0.0" izx="0.0" izy="0.0" izz="3.5976895e-06"/>
    </inertial>
    <collision>
      <origin rpy="0 0 0" xyz="0 0 0"/>
      <geometry>
        <mesh filename="package://commissioning_robot/stl/ots-barrel-display_s.stl"/>
      </geometry>
    </collision>
  </link>
  <!-- <xacro:INSERT_GAZEBO_PHYSICS_UNIT  suffix="${suffix}" mu1="${1}" mu2="${1}" kp="${2e8}" kd="${0.1}" df="${0.03}" color="Gazebo/GreyGradientSky"/> -->
  <!-- <xacro:INSERT_GAZEBO_PHYSICS_UNIT  suffix="${suffix}" mu1="${1}" mu2="${1}" kp="${1}" kd="${1}" df="${0}" color="Gazebo/GreyGradientSky"/> -->
  <gazebo reference="mechanum1_link_barrel2">
    <material>Gazebo/GreyGradientSky</material>
    <dampingFactor>0.01</dampingFactor>
  </gazebo>
  <joint name="mechanum1_link_barrel2_joint" type="continuous">
    <parent link="mechanum1_link"/>
    <child link="mechanum1_link_barrel2"/>
    <origin rpy="0.6981317007977318 0.6016498987064663 0.5048442081024438" xyz="0 0.030863930613263625 0.025897912794270665"/>
    <axis xyz="1 0 0"/>
    <!-- <dynamics damping="1e-4"/> -->
    <!-- <limit effort="10000" velocity="10000"/> -->
    <!-- <safety_controller k_velocity="10" k_position="15" soft_lower_limit="-2.0" soft_upper_limit="0.5" /> -->
    <!-- <safety_controller k_velocity="10" k_position="15" /> -->
    <!-- <dynamics friction="10"/> -->
  </joint>
  <transmission name="mechanum1_link_barrel2_trans">
    <type>transmission_interface/SimpleTransmission</type>
    <joint name="mechanum1_link_barrel2_joint">
      <hardwareInterface>hardware_interface/EffortJointInterface</hardwareInterface>
    </joint>
    <actuator name="mechanum1_link_barrel2_motor">
      <hardwareInterface>hardware_interface/EffortJointInterface</hardwareInterface>
      <mechanismReduction>1</mechanismReduction>
    </actuator>
  </transmission>
  <link name="mechanum1_link_barrel3">
    <visual>
      <geometry>
        <mesh filename="package://commissioning_robot/stl/ots-barrel-display_s.stl"/>
      </geometry>
      <origin rpy="0 0 0" xyz="0 0 0"/>
      <material name="blue"/>
    </visual>
    <inertial>
      <origin rpy="0 0 0" xyz="0 0 0"/>
      <mass value="0.020168905"/>
      <inertia ixx="9.115874e-07" ixy="0.0" ixz="0.0" iyx="0.0" iyy="3.5976895e-06" iyz="0.0" izx="0.0" izy="0.0" izz="3.5976895e-06"/>
    </inertial>
    <collision>
      <origin rpy="0 0 0" xyz="0 0 0"/>
      <geometry>
        <mesh filename="package://commissioning_robot/stl/ots-barrel-display_s.stl"/>
      </geometry>
    </collision>
  </link>
  <!-- <xacro:INSERT_GAZEBO_PHYSICS_UNIT  suffix="${suffix}" mu1="${1}" mu2="${1}" kp="${2e8}" kd="${0.1}" df="${0.03}" color="Gazebo/GreyGradientSky"/> -->
  <!-- <xacro:INSERT_GAZEBO_PHYSICS_UNIT  suffix="${suffix}" mu1="${1}" mu2="${1}" kp="${1}" kd="${1}" df="${0}" color="Gazebo/GreyGradientSky"/> -->
  <gazebo reference="mechanum1_link_barrel3">
    <material>Gazebo/GreyGradientSky</material>
    <dampingFactor>0.01</dampingFactor>
  </gazebo>
  <joint name="mechanum1_link_barrel3_joint" type="continuous">
    <parent link="mechanum1_link"/>
    <child link="mechanum1_link_barrel3"/>
    <origin rpy="1.3962634015954636 0.13638295981692095 0.7734662005153561" xyz="0 0.006996285078200626 0.03967790436886186"/>
    <axis xyz="1 0 0"/>
    <!-- <dynamics damping="1e-4"/> -->
    <!-- <limit effort="10000" velocity="10000"/> -->
    <!-- <safety_controller k_velocity="10" k_position="15" soft_lower_limit="-2.0" soft_upper_limit="0.5" /> -->
    <!-- <safety_controller k_velocity="10" k_position="15" /> -->
    <!-- <dynamics friction="10"/> -->
  </joint>
  <transmission name="mechanum1_link_barrel3_trans">
    <type>transmission_interface/SimpleTransmission</type>
    <joint name="mechanum1_link_barrel3_joint">
      <hardwareInterface>hardware_interface/EffortJointInterface</hardwareInterface>
    </joint>
    <actuator name="mechanum1_link_barrel3_motor">
      <hardwareInterface>hardware_interface/EffortJointInterface</hardwareInterface>
      <mechanismReduction>1</mechanismReduction>
    </actuator>
  </transmission>
  <link name="mechanum1_link_barrel4">
    <visual>
      <geometry>
        <mesh filename="package://commissioning_robot/stl/ots-barrel-display_s.stl"/>
      </geometry>
      <origin rpy="0 0 0" xyz="0 0 0"/>
      <material name="blue"/>
    </visual>
    <inertial>
      <origin rpy="0 0 0" xyz="0 0 0"/>
      <mass value="0.020168905"/>
      <inertia ixx="9.115874e-07" ixy="0.0" ixz="0.0" iyx="0.0" iyy="3.5976895e-06" iyz="0.0" izx="0.0" izy="0.0" izz="3.5976895e-06"/>
    </inertial>
    <collision>
      <origin rpy="0 0 0" xyz="0 0 0"/>
      <geometry>
        <mesh filename="package://commissioning_robot/stl/ots-barrel-display_s.stl"/>
      </geometry>
    </collision>
  </link>
  <!-- <xacro:INSERT_GAZEBO_PHYSICS_UNIT  suffix="${suffix}" mu1="${1}" mu2="${1}" kp="${2e8}" kd="${0.1}" df="${0.03}" color="Gazebo/GreyGradientSky"/> -->
  <!-- <xacro:INSERT_GAZEBO_PHYSICS_UNIT  suffix="${suffix}" mu1="${1}" mu2="${1}" kp="${1}" kd="${1}" df="${0}" color="Gazebo/GreyGradientSky"/> -->
  <gazebo reference="mechanum1_link_barrel4">
    <material>Gazebo/GreyGradientSky</material>
    <dampingFactor>0.01</dampingFactor>
  </gazebo>
  <joint name="mechanum1_link_barrel4_joint" type="continuous">
    <parent link="mechanum1_link"/>
    <child link="mechanum1_link_barrel4"/>
    <origin rpy="2.0943951023931953 -0.392699081698724 0.6801747615878317" xyz="0 -0.02014499999999999 0.03489216351847504"/>
    <axis xyz="1 0 0"/>
    <!-- <dynamics damping="1e-4"/> -->
    <!-- <limit effort="10000" velocity="10000"/> -->
    <!-- <safety_controller k_velocity="10" k_position="15" soft_lower_limit="-2.0" soft_upper_limit="0.5" /> -->
    <!-- <safety_controller k_velocity="10" k_position="15" /> -->
    <!-- <dynamics friction="10"/> -->
  </joint>
  <transmission name="mechanum1_link_barrel4_trans">
    <type>transmission_interface/SimpleTransmission</type>
    <joint name="mechanum1_link_barrel4_joint">
      <hardwareInterface>hardware_interface/EffortJointInterface</hardwareInterface>
    </joint>
    <actuator name="mechanum1_link_barrel4_motor">
      <hardwareInterface>hardware_interface/EffortJointInterface</hardwareInterface>
      <mechanismReduction>1</mechanismReduction>
    </actuator>
  </transmission>
  <link name="mechanum1_link_barrel5">
    <visual>
      <geometry>
        <mesh filename="package://commissioning_robot/stl/ots-barrel-display_s.stl"/>
      </geometry>
      <origin rpy="0 0 0" xyz="0 0 0"/>
      <material name="blue"/>
    </visual>
    <inertial>
      <origin rpy="0 0 0" xyz="0 0 0"/>
      <mass value="0.020168905"/>
      <inertia ixx="9.115874e-07" ixy="0.0" ixz="0.0" iyx="0.0" iyy="3.5976895e-06" iyz="0.0" izx="0.0" izy="0.0" izz="3.5976895e-06"/>
    </inertial>
    <collision>
      <origin rpy="0 0 0" xyz="0 0 0"/>
      <geometry>
        <mesh filename="package://commissioning_robot/stl/ots-barrel-display_s.stl"/>
      </geometry>
    </collision>
  </link>
  <!-- <xacro:INSERT_GAZEBO_PHYSICS_UNIT  suffix="${suffix}" mu1="${1}" mu2="${1}" kp="${2e8}" kd="${0.1}" df="${0.03}" color="Gazebo/GreyGradientSky"/> -->
  <!-- <xacro:INSERT_GAZEBO_PHYSICS_UNIT  suffix="${suffix}" mu1="${1}" mu2="${1}" kp="${1}" kd="${1}" df="${0}" color="Gazebo/GreyGradientSky"/> -->
  <gazebo reference="mechanum1_link_barrel5">
    <material>Gazebo/GreyGradientSky</material>
    <dampingFactor>0.01</dampingFactor>
  </gazebo>
  <joint name="mechanum1_link_barrel5_joint" type="continuous">
    <parent link="mechanum1_link"/>
    <child link="mechanum1_link_barrel5"/>
    <origin rpy="2.792526803190927 -0.7380328585233872 0.26862199241291235" xyz="0 -0.03786021569146424 0.0137799915745912"/>
    <axis xyz="1 0 0"/>
    <!-- <dynamics damping="1e-4"/> -->
    <!-- <limit effort="10000" velocity="10000"/> -->
    <!-- <safety_controller k_velocity="10" k_position="15" soft_lower_limit="-2.0" soft_upper_limit="0.5" /> -->
    <!-- <safety_controller k_velocity="10" k_position="15" /> -->
    <!-- <dynamics friction="10"/> -->
  </joint>
  <transmission name="mechanum1_link_barrel5_trans">
    <type>transmission_interface/SimpleTransmission</type>
    <joint name="mechanum1_link_barrel5_joint">
      <hardwareInterface>hardware_interface/EffortJointInterface</hardwareInterface>
    </joint>
    <actuator name="mechanum1_link_barrel5_motor">
      <hardwareInterface>hardware_interface/EffortJointInterface</hardwareInterface>
      <mechanismReduction>1</mechanismReduction>
    </actuator>
  </transmission>
  <link name="mechanum1_link_barrel6">
    <visual>
      <geometry>
        <mesh filename="package://commissioning_robot/stl/ots-barrel-display_s.stl"/>
      </geometry>
      <origin rpy="0 0 0" xyz="0 0 0"/>
      <material name="blue"/>
    </visual>
    <inertial>
      <origin rpy="0 0 0" xyz="0 0 0"/>
      <mass value="0.020168905"/>
      <inertia ixx="9.115874e-07" ixy="0.0" ixz="0.0" iyx="0.0" iyy="3.5976895e-06" iyz="0.0" izx="0.0" izy="0.0" izz="3.5976895e-06"/>
    </inertial>
    <collision>
      <origin rpy="0 0 0" xyz="0 0 0"/>
      <geometry>
        <mesh filename="package://commissioning_robot/stl/ots-barrel-display_s.stl"/>
      </geometry>
    </collision>
  </link>
  <!-- <xacro:INSERT_GAZEBO_PHYSICS_UNIT  suffix="${suffix}" mu1="${1}" mu2="${1}" kp="${2e8}" kd="${0.1}" df="${0.03}" color="Gazebo/GreyGradientSky"/> -->
  <!-- <xacro:INSERT_GAZEBO_PHYSICS_UNIT  suffix="${suffix}" mu1="${1}" mu2="${1}" kp="${1}" kd="${1}" df="${0}" color="Gazebo/GreyGradientSky"/> -->
  <gazebo reference="mechanum1_link_barrel6">
    <material>Gazebo/GreyGradientSky</material>
    <dampingFactor>0.01</dampingFactor>
  </gazebo>
  <joint name="mechanum1_link_barrel6_joint" type="continuous">
    <parent link="mechanum1_link"/>
    <child link="mechanum1_link_barrel6"/>
    <origin rpy="3.490658503988659 -0.7380328585233873 -0.2686219924129122" xyz="0 -0.03786021569146425 -0.01377999157459119"/>
    <axis xyz="1 0 0"/>
    <!-- <dynamics damping="1e-4"/> -->
    <!-- <limit effort="10000" velocity="10000"/> -->
    <!-- <safety_controller k_velocity="10" k_position="15" soft_lower_limit="-2.0" soft_upper_limit="0.5" /> -->
    <!-- <safety_controller k_velocity="10" k_position="15" /> -->
    <!-- <dynamics friction="10"/> -->
  </joint>
  <transmission name="mechanum1_link_barrel6_trans">
    <type>transmission_interface/SimpleTransmission</type>
    <joint name="mechanum1_link_barrel6_joint">
      <hardwareInterface>hardware_interface/EffortJointInterface</hardwareInterface>
    </joint>
    <actuator name="mechanum1_link_barrel6_motor">
      <hardwareInterface>hardware_interface/EffortJointInterface</hardwareInterface>
      <mechanismReduction>1</mechanismReduction>
    </actuator>
  </transmission>
  <link name="mechanum1_link_barrel7">
    <visual>
      <geometry>
        <mesh filename="package://commissioning_robot/stl/ots-barrel-display_s.stl"/>
      </geometry>
      <origin rpy="0 0 0" xyz="0 0 0"/>
      <material name="blue"/>
    </visual>
    <inertial>
      <origin rpy="0 0 0" xyz="0 0 0"/>
      <mass value="0.020168905"/>
      <inertia ixx="9.115874e-07" ixy="0.0" ixz="0.0" iyx="0.0" iyy="3.5976895e-06" iyz="0.0" izx="0.0" izy="0.0" izz="3.5976895e-06"/>
    </inertial>
    <collision>
      <origin rpy="0 0 0" xyz="0 0 0"/>
      <geometry>
        <mesh filename="package://commissioning_robot/stl/ots-barrel-display_s.stl"/>
      </geometry>
    </collision>
  </link>
  <!-- <xacro:INSERT_GAZEBO_PHYSICS_UNIT  suffix="${suffix}" mu1="${1}" mu2="${1}" kp="${2e8}" kd="${0.1}" df="${0.03}" color="Gazebo/GreyGradientSky"/> -->
  <!-- <xacro:INSERT_GAZEBO_PHYSICS_UNIT  suffix="${suffix}" mu1="${1}" mu2="${1}" kp="${1}" kd="${1}" df="${0}" color="Gazebo/GreyGradientSky"/> -->
  <gazebo reference="mechanum1_link_barrel7">
    <material>Gazebo/GreyGradientSky</material>
    <dampingFactor>0.01</dampingFactor>
  </gazebo>
  <joint name="mechanum1_link_barrel7_joint" type="continuous">
    <parent link="mechanum1_link"/>
    <child link="mechanum1_link_barrel7"/>
    <origin rpy="4.1887902047863905 -0.3926990816987245 -0.6801747615878314" xyz="0 -0.020145000000000017 -0.034892163518475024"/>
    <axis xyz="1 0 0"/>
    <!-- <dynamics damping="1e-4"/> -->
    <!-- <limit effort="10000" velocity="10000"/> -->
    <!-- <safety_controller k_velocity="10" k_position="15" soft_lower_limit="-2.0" soft_upper_limit="0.5" /> -->
    <!-- <safety_controller k_velocity="10" k_position="15" /> -->
    <!-- <dynamics friction="10"/> -->
  </joint>
  <transmission name="mechanum1_link_barrel7_trans">
    <type>transmission_interface/SimpleTransmission</type>
    <joint name="mechanum1_link_barrel7_joint">
      <hardwareInterface>hardware_interface/EffortJointInterface</hardwareInterface>
    </joint>
    <actuator name="mechanum1_link_barrel7_motor">
      <hardwareInterface>hardware_interface/EffortJointInterface</hardwareInterface>
      <mechanismReduction>1</mechanismReduction>
    </actuator>
  </transmission>
  <link name="mechanum1_link_barrel8">
    <visual>
      <geometry>
        <mesh filename="package://commissioning_robot/stl/ots-barrel-display_s.stl"/>
      </geometry>
      <origin rpy="0 0 0" xyz="0 0 0"/>
      <material name="blue"/>
    </visual>
    <inertial>
      <origin rpy="0 0 0" xyz="0 0 0"/>
      <mass value="0.020168905"/>
      <inertia ixx="9.115874e-07" ixy="0.0" ixz="0.0" iyx="0.0" iyy="3.5976895e-06" iyz="0.0" izx="0.0" izy="0.0" izz="3.5976895e-06"/>
    </inertial>
    <collision>
      <origin rpy="0 0 0" xyz="0 0 0"/>
      <geometry>
        <mesh filename="package://commissioning_robot/stl/ots-barrel-display_s.stl"/>
      </geometry>
    </collision>
  </link>
  <!-- <xacro:INSERT_GAZEBO_PHYSICS_UNIT  suffix="${suffix}" mu1="${1}" mu2="${1}" kp="${2e8}" kd="${0.1}" df="${0.03}" color="Gazebo/GreyGradientSky"/> -->
  <!-- <xacro:INSERT_GAZEBO_PHYSICS_UNIT  suffix="${suffix}" mu1="${1}" mu2="${1}" kp="${1}" kd="${1}" df="${0}" color="Gazebo/GreyGradientSky"/> -->
  <gazebo reference="mechanum1_link_barrel8">
    <material>Gazebo/GreyGradientSky</material>
    <dampingFactor>0.01</dampingFactor>
  </gazebo>
  <joint name="mechanum1_link_barrel8_joint" type="continuous">
    <parent link="mechanum1_link"/>
    <child link="mechanum1_link_barrel8"/>
    <origin rpy="4.886921905584122 0.13638295981692058 -0.7734662005153561" xyz="0 0.006996285078200609 -0.039677904368861865"/>
    <axis xyz="1 0 0"/>
    <!-- <dynamics damping="1e-4"/> -->
    <!-- <limit effort="10000" velocity="10000"/> -->
    <!-- <safety_controller k_velocity="10" k_position="15" soft_lower_limit="-2.0" soft_upper_limit="0.5" /> -->
    <!-- <safety_controller k_velocity="10" k_position="15" /> -->
    <!-- <dynamics friction="10"/> -->
  </joint>
  <transmission name="mechanum1_link_barrel8_trans">
    <type>transmission_interface/SimpleTransmission</type>
    <joint name="mechanum1_link_barrel8_joint">
      <hardwareInterface>hardware_interface/EffortJointInterface</hardwareInterface>
    </joint>
    <actuator name="mechanum1_link_barrel8_motor">
      <hardwareInterface>hardware_interface/EffortJointInterface</hardwareInterface>
      <mechanismReduction>1</mechanismReduction>
    </actuator>
  </transmission>
  <link name="mechanum1_link_barrel9">
    <visual>
      <geometry>
        <mesh filename="package://commissioning_robot/stl/ots-barrel-display_s.stl"/>
      </geometry>
      <origin rpy="0 0 0" xyz="0 0 0"/>
      <material name="blue"/>
    </visual>
    <inertial>
      <origin rpy="0 0 0" xyz="0 0 0"/>
      <mass value="0.020168905"/>
      <inertia ixx="9.115874e-07" ixy="0.0" ixz="0.0" iyx="0.0" iyy="3.5976895e-06" iyz="0.0" izx="0.0" izy="0.0" izz="3.5976895e-06"/>
    </inertial>
    <collision>
      <origin rpy="0 0 0" xyz="0 0 0"/>
      <geometry>
        <mesh filename="package://commissioning_robot/stl/ots-barrel-display_s.stl"/>
      </geometry>
    </collision>
  </link>
  <!-- <xacro:INSERT_GAZEBO_PHYSICS_UNIT  suffix="${suffix}" mu1="${1}" mu2="${1}" kp="${2e8}" kd="${0.1}" df="${0.03}" color="Gazebo/GreyGradientSky"/> -->
  <!-- <xacro:INSERT_GAZEBO_PHYSICS_UNIT  suffix="${suffix}" mu1="${1}" mu2="${1}" kp="${1}" kd="${1}" df="${0}" color="Gazebo/GreyGradientSky"/> -->
  <gazebo reference="mechanum1_link_barrel9">
    <material>Gazebo/GreyGradientSky</material>
    <dampingFactor>0.01</dampingFactor>
  </gazebo>
  <joint name="mechanum1_link_barrel9_joint" type="continuous">
    <parent link="mechanum1_link"/>
    <child link="mechanum1_link_barrel9"/>
    <origin rpy="5.585053606381854 0.6016498987064662 -0.504844208102444" xyz="0 0.030863930613263615 -0.02589791279427068"/>
    <axis xyz="1 0 0"/>
    <!-- <dynamics damping="1e-4"/> -->
    <!-- <limit effort="10000" velocity="10000"/> -->
    <!-- <safety_controller k_velocity="10" k_position="15" soft_lower_limit="-2.0" soft_upper_limit="0.5" /> -->
    <!-- <safety_controller k_velocity="10" k_position="15" /> -->
    <!-- <dynamics friction="10"/> -->
  </joint>
  <transmission name="mechanum1_link_barrel9_trans">
    <type>transmission_interface/SimpleTransmission</type>
    <joint name="mechanum1_link_barrel9_joint">
      <hardwareInterface>hardware_interface/EffortJointInterface</hardwareInterface>
    </joint>
    <actuator name="mechanum1_link_barrel9_motor">
      <hardwareInterface>hardware_interface/EffortJointInterface</hardwareInterface>
      <mechanismReduction>1</mechanismReduction>
    </actuator>
  </transmission>
  <link name="mechanum2_link">
    <visual>
      <geometry>
        <mesh filename="package://commissioning_robot/stl/03-asm-mechanum-l.stl"/>
      </geometry>
      <origin rpy="0 0 0" xyz="0 0 0"/>
      <material name="blue"/>
    </visual>
    <inertial>
      <origin rpy="0 0 0" xyz="0 0 0"/>
      <mass value="0.2283143"/>
      <inertia ixx="0.00013964271" ixy="-2.4376656e-7" ixz="-4.0742095e-08" iyx="-2.4376656e-07" iyy="0.00014237359" iyz="1.5005847e-08" izx="-4.0742095e-08" izy="1.5005847e-08" izz="0.00014228689"/>
    </inertial>
    <collision>
      <origin rpy="0 0 0" xyz="0 0 0"/>
      <geometry>
        <box size="0 0 0"/>
      </geometry>
    </collision>
  </link>
  <gazebo reference="mechanum2_link">
    <material>Gazebo/Grey</material>
    <mu1>1</mu1>
    <mu2>1</mu2>
    <kp>20000000000.0</kp>
    <kd>0.01</kd>
    <dampingFactor>0.01</dampingFactor>
    <!-- <minDepth>0.001</minDepth> -->
    <!-- <maxVel>0.01</maxVel> -->
    <!-- <turnGravityOff>true</turnGravityOff> -->
  </gazebo>
  <link name="mechanum2_link_barrel1">
    <visual>
      <geometry>
        <mesh filename="package://commissioning_robot/stl/ots-barrel-display_s.stl"/>
      </geometry>
      <origin rpy="0 0 0" xyz="0 0 0"/>
      <material name="blue"/>
    </visual>
    <inertial>
      <origin rpy="0 0 0" xyz="0 0 0"/>
      <mass value="0.020168905"/>
      <inertia ixx="9.115874e-07" ixy="0.0" ixz="0.0" iyx="0.0" iyy="3.5976895e-06" iyz="0.0" izx="0.0" izy="0.0" izz="3.5976895e-06"/>
    </inertial>
    <collision>
      <origin rpy="0 0 0" xyz="0 0 0"/>
      <geometry>
        <mesh filename="package://commissioning_robot/stl/ots-barrel-display_s.stl"/>
      </geometry>
    </collision>
  </link>
  <!-- <xacro:INSERT_GAZEBO_PHYSICS_UNIT  suffix="${suffix}" mu1="${1}" mu2="${1}" kp="${2e8}" kd="${0.1}" df="${0.03}" color="Gazebo/GreyGradientSky"/> -->
  <!-- <xacro:INSERT_GAZEBO_PHYSICS_UNIT  suffix="${suffix}" mu1="${1}" mu2="${1}" kp="${1}" kd="${1}" df="${0}" color="Gazebo/GreyGradientSky"/> -->
  <gazebo reference="mechanum2_link_barrel1">
    <material>Gazebo/GreyGradientSky</material>
    <dampingFactor>0.01</dampingFactor>
  </gazebo>
  <joint name="mechanum2_link_barrel1_joint" type="continuous">
    <parent link="mechanum2_link"/>
    <child link="mechanum2_link_barrel1"/>
    <origin rpy="0.0 -0.7853981633974483 -0.0" xyz="0 0.04029 0.0"/>
    <axis xyz="1 0 0"/>
    <!-- <dynamics damping="1e-4"/> -->
    <!-- <limit effort="10000" velocity="10000"/> -->
    <!-- <safety_controller k_velocity="10" k_position="15" soft_lower_limit="-2.0" soft_upper_limit="0.5" /> -->
    <!-- <safety_controller k_velocity="10" k_position="15" /> -->
    <!-- <dynamics friction="10"/> -->
  </joint>
  <transmission name="mechanum2_link_barrel1_trans">
    <type>transmission_interface/SimpleTransmission</type>
    <joint name="mechanum2_link_barrel1_joint">
      <hardwareInterface>hardware_interface/EffortJointInterface</hardwareInterface>
    </joint>
    <actuator name="mechanum2_link_barrel1_motor">
      <hardwareInterface>hardware_interface/EffortJointInterface</hardwareInterface>
      <mechanismReduction>1</mechanismReduction>
    </actuator>
  </transmission>
  <link name="mechanum2_link_barrel2">
    <visual>
      <geometry>
        <mesh filename="package://commissioning_robot/stl/ots-barrel-display_s.stl"/>
      </geometry>
      <origin rpy="0 0 0" xyz="0 0 0"/>
      <material name="blue"/>
    </visual>
    <inertial>
      <origin rpy="0 0 0" xyz="0 0 0"/>
      <mass value="0.020168905"/>
      <inertia ixx="9.115874e-07" ixy="0.0" ixz="0.0" iyx="0.0" iyy="3.5976895e-06" iyz="0.0" izx="0.0" izy="0.0" izz="3.5976895e-06"/>
    </inertial>
    <collision>
      <origin rpy="0 0 0" xyz="0 0 0"/>
      <geometry>
        <mesh filename="package://commissioning_robot/stl/ots-barrel-display_s.stl"/>
      </geometry>
    </collision>
  </link>
  <!-- <xacro:INSERT_GAZEBO_PHYSICS_UNIT  suffix="${suffix}" mu1="${1}" mu2="${1}" kp="${2e8}" kd="${0.1}" df="${0.03}" color="Gazebo/GreyGradientSky"/> -->
  <!-- <xacro:INSERT_GAZEBO_PHYSICS_UNIT  suffix="${suffix}" mu1="${1}" mu2="${1}" kp="${1}" kd="${1}" df="${0}" color="Gazebo/GreyGradientSky"/> -->
  <gazebo reference="mechanum2_link_barrel2">
    <material>Gazebo/GreyGradientSky</material>
    <dampingFactor>0.01</dampingFactor>
  </gazebo>
  <joint name="mechanum2_link_barrel2_joint" type="continuous">
    <parent link="mechanum2_link"/>
    <child link="mechanum2_link_barrel2"/>
    <origin rpy="0.6981317007977318 -0.6016498987064663 -0.5048442081024438" xyz="0 0.030863930613263625 0.025897912794270665"/>
    <axis xyz="1 0 0"/>
    <!-- <dynamics damping="1e-4"/> -->
    <!-- <limit effort="10000" velocity="10000"/> -->
    <!-- <safety_controller k_velocity="10" k_position="15" soft_lower_limit="-2.0" soft_upper_limit="0.5" /> -->
    <!-- <safety_controller k_velocity="10" k_position="15" /> -->
    <!-- <dynamics friction="10"/> -->
  </joint>
  <transmission name="mechanum2_link_barrel2_trans">
    <type>transmission_interface/SimpleTransmission</type>
    <joint name="mechanum2_link_barrel2_joint">
      <hardwareInterface>hardware_interface/EffortJointInterface</hardwareInterface>
    </joint>
    <actuator name="mechanum2_link_barrel2_motor">
      <hardwareInterface>hardware_interface/EffortJointInterface</hardwareInterface>
      <mechanismReduction>1</mechanismReduction>
    </actuator>
  </transmission>
  <link name="mechanum2_link_barrel3">
    <visual>
      <geometry>
        <mesh filename="package://commissioning_robot/stl/ots-barrel-display_s.stl"/>
      </geometry>
      <origin rpy="0 0 0" xyz="0 0 0"/>
      <material name="blue"/>
    </visual>
    <inertial>
      <origin rpy="0 0 0" xyz="0 0 0"/>
      <mass value="0.020168905"/>
      <inertia ixx="9.115874e-07" ixy="0.0" ixz="0.0" iyx="0.0" iyy="3.5976895e-06" iyz="0.0" izx="0.0" izy="0.0" izz="3.5976895e-06"/>
    </inertial>
    <collision>
      <origin rpy="0 0 0" xyz="0 0 0"/>
      <geometry>
        <mesh filename="package://commissioning_robot/stl/ots-barrel-display_s.stl"/>
      </geometry>
    </collision>
  </link>
  <!-- <xacro:INSERT_GAZEBO_PHYSICS_UNIT  suffix="${suffix}" mu1="${1}" mu2="${1}" kp="${2e8}" kd="${0.1}" df="${0.03}" color="Gazebo/GreyGradientSky"/> -->
  <!-- <xacro:INSERT_GAZEBO_PHYSICS_UNIT  suffix="${suffix}" mu1="${1}" mu2="${1}" kp="${1}" kd="${1}" df="${0}" color="Gazebo/GreyGradientSky"/> -->
  <gazebo reference="mechanum2_link_barrel3">
    <material>Gazebo/GreyGradientSky</material>
    <dampingFactor>0.01</dampingFactor>
  </gazebo>
  <joint name="mechanum2_link_barrel3_joint" type="continuous">
    <parent link="mechanum2_link"/>
    <child link="mechanum2_link_barrel3"/>
    <origin rpy="1.3962634015954636 -0.13638295981692095 -0.7734662005153561" xyz="0 0.006996285078200626 0.03967790436886186"/>
    <axis xyz="1 0 0"/>
    <!-- <dynamics damping="1e-4"/> -->
    <!-- <limit effort="10000" velocity="10000"/> -->
    <!-- <safety_controller k_velocity="10" k_position="15" soft_lower_limit="-2.0" soft_upper_limit="0.5" /> -->
    <!-- <safety_controller k_velocity="10" k_position="15" /> -->
    <!-- <dynamics friction="10"/> -->
  </joint>
  <transmission name="mechanum2_link_barrel3_trans">
    <type>transmission_interface/SimpleTransmission</type>
    <joint name="mechanum2_link_barrel3_joint">
      <hardwareInterface>hardware_interface/EffortJointInterface</hardwareInterface>
    </joint>
    <actuator name="mechanum2_link_barrel3_motor">
      <hardwareInterface>hardware_interface/EffortJointInterface</hardwareInterface>
      <mechanismReduction>1</mechanismReduction>
    </actuator>
  </transmission>
  <link name="mechanum2_link_barrel4">
    <visual>
      <geometry>
        <mesh filename="package://commissioning_robot/stl/ots-barrel-display_s.stl"/>
      </geometry>
      <origin rpy="0 0 0" xyz="0 0 0"/>
      <material name="blue"/>
    </visual>
    <inertial>
      <origin rpy="0 0 0" xyz="0 0 0"/>
      <mass value="0.020168905"/>
      <inertia ixx="9.115874e-07" ixy="0.0" ixz="0.0" iyx="0.0" iyy="3.5976895e-06" iyz="0.0" izx="0.0" izy="0.0" izz="3.5976895e-06"/>
    </inertial>
    <collision>
      <origin rpy="0 0 0" xyz="0 0 0"/>
      <geometry>
        <mesh filename="package://commissioning_robot/stl/ots-barrel-display_s.stl"/>
      </geometry>
    </collision>
  </link>
  <!-- <xacro:INSERT_GAZEBO_PHYSICS_UNIT  suffix="${suffix}" mu1="${1}" mu2="${1}" kp="${2e8}" kd="${0.1}" df="${0.03}" color="Gazebo/GreyGradientSky"/> -->
  <!-- <xacro:INSERT_GAZEBO_PHYSICS_UNIT  suffix="${suffix}" mu1="${1}" mu2="${1}" kp="${1}" kd="${1}" df="${0}" color="Gazebo/GreyGradientSky"/> -->
  <gazebo reference="mechanum2_link_barrel4">
    <material>Gazebo/GreyGradientSky</material>
    <dampingFactor>0.01</dampingFactor>
  </gazebo>
  <joint name="mechanum2_link_barrel4_joint" type="continuous">
    <parent link="mechanum2_link"/>
    <child link="mechanum2_link_barrel4"/>
    <origin rpy="2.0943951023931953 0.392699081698724 -0.6801747615878317" xyz="0 -0.02014499999999999 0.03489216351847504"/>
    <axis xyz="1 0 0"/>
    <!-- <dynamics damping="1e-4"/> -->
    <!-- <limit effort="10000" velocity="10000"/> -->
    <!-- <safety_controller k_velocity="10" k_position="15" soft_lower_limit="-2.0" soft_upper_limit="0.5" /> -->
    <!-- <safety_controller k_velocity="10" k_position="15" /> -->
    <!-- <dynamics friction="10"/> -->
  </joint>
  <transmission name="mechanum2_link_barrel4_trans">
    <type>transmission_interface/SimpleTransmission</type>
    <joint name="mechanum2_link_barrel4_joint">
      <hardwareInterface>hardware_interface/EffortJointInterface</hardwareInterface>
    </joint>
    <actuator name="mechanum2_link_barrel4_motor">
      <hardwareInterface>hardware_interface/EffortJointInterface</hardwareInterface>
      <mechanismReduction>1</mechanismReduction>
    </actuator>
  </transmission>
  <link name="mechanum2_link_barrel5">
    <visual>
      <geometry>
        <mesh filename="package://commissioning_robot/stl/ots-barrel-display_s.stl"/>
      </geometry>
      <origin rpy="0 0 0" xyz="0 0 0"/>
      <material name="blue"/>
    </visual>
    <inertial>
      <origin rpy="0 0 0" xyz="0 0 0"/>
      <mass value="0.020168905"/>
      <inertia ixx="9.115874e-07" ixy="0.0" ixz="0.0" iyx="0.0" iyy="3.5976895e-06" iyz="0.0" izx="0.0" izy="0.0" izz="3.5976895e-06"/>
    </inertial>
    <collision>
      <origin rpy="0 0 0" xyz="0 0 0"/>
      <geometry>
        <mesh filename="package://commissioning_robot/stl/ots-barrel-display_s.stl"/>
      </geometry>
    </collision>
  </link>
  <!-- <xacro:INSERT_GAZEBO_PHYSICS_UNIT  suffix="${suffix}" mu1="${1}" mu2="${1}" kp="${2e8}" kd="${0.1}" df="${0.03}" color="Gazebo/GreyGradientSky"/> -->
  <!-- <xacro:INSERT_GAZEBO_PHYSICS_UNIT  suffix="${suffix}" mu1="${1}" mu2="${1}" kp="${1}" kd="${1}" df="${0}" color="Gazebo/GreyGradientSky"/> -->
  <gazebo reference="mechanum2_link_barrel5">
    <material>Gazebo/GreyGradientSky</material>
    <dampingFactor>0.01</dampingFactor>
  </gazebo>
  <joint name="mechanum2_link_barrel5_joint" type="continuous">
    <parent link="mechanum2_link"/>
    <child link="mechanum2_link_barrel5"/>
    <origin rpy="2.792526803190927 0.7380328585233872 -0.26862199241291235" xyz="0 -0.03786021569146424 0.0137799915745912"/>
    <axis xyz="1 0 0"/>
    <!-- <dynamics damping="1e-4"/> -->
    <!-- <limit effort="10000" velocity="10000"/> -->
    <!-- <safety_controller k_velocity="10" k_position="15" soft_lower_limit="-2.0" soft_upper_limit="0.5" /> -->
    <!-- <safety_controller k_velocity="10" k_position="15" /> -->
    <!-- <dynamics friction="10"/> -->
  </joint>
  <transmission name="mechanum2_link_barrel5_trans">
    <type>transmission_interface/SimpleTransmission</type>
    <joint name="mechanum2_link_barrel5_joint">
      <hardwareInterface>hardware_interface/EffortJointInterface</hardwareInterface>
    </joint>
    <actuator name="mechanum2_link_barrel5_motor">
      <hardwareInterface>hardware_interface/EffortJointInterface</hardwareInterface>
      <mechanismReduction>1</mechanismReduction>
    </actuator>
  </transmission>
  <link name="mechanum2_link_barrel6">
    <visual>
      <geometry>
        <mesh filename="package://commissioning_robot/stl/ots-barrel-display_s.stl"/>
      </geometry>
      <origin rpy="0 0 0" xyz="0 0 0"/>
      <material name="blue"/>
    </visual>
    <inertial>
      <origin rpy="0 0 0" xyz="0 0 0"/>
      <mass value="0.020168905"/>
      <inertia ixx="9.115874e-07" ixy="0.0" ixz="0.0" iyx="0.0" iyy="3.5976895e-06" iyz="0.0" izx="0.0" izy="0.0" izz="3.5976895e-06"/>
    </inertial>
    <collision>
      <origin rpy="0 0 0" xyz="0 0 0"/>
      <geometry>
        <mesh filename="package://commissioning_robot/stl/ots-barrel-display_s.stl"/>
      </geometry>
    </collision>
  </link>
  <!-- <xacro:INSERT_GAZEBO_PHYSICS_UNIT  suffix="${suffix}" mu1="${1}" mu2="${1}" kp="${2e8}" kd="${0.1}" df="${0.03}" color="Gazebo/GreyGradientSky"/> -->
  <!-- <xacro:INSERT_GAZEBO_PHYSICS_UNIT  suffix="${suffix}" mu1="${1}" mu2="${1}" kp="${1}" kd="${1}" df="${0}" color="Gazebo/GreyGradientSky"/> -->
  <gazebo reference="mechanum2_link_barrel6">
    <material>Gazebo/GreyGradientSky</material>
    <dampingFactor>0.01</dampingFactor>
  </gazebo>
  <joint name="mechanum2_link_barrel6_joint" type="continuous">
    <parent link="mechanum2_link"/>
    <child link="mechanum2_link_barrel6"/>
    <origin rpy="3.490658503988659 0.7380328585233873 0.2686219924129122" xyz="0 -0.03786021569146425 -0.01377999157459119"/>
    <axis xyz="1 0 0"/>
    <!-- <dynamics damping="1e-4"/> -->
    <!-- <limit effort="10000" velocity="10000"/> -->
    <!-- <safety_controller k_velocity="10" k_position="15" soft_lower_limit="-2.0" soft_upper_limit="0.5" /> -->
    <!-- <safety_controller k_velocity="10" k_position="15" /> -->
    <!-- <dynamics friction="10"/> -->
  </joint>
  <transmission name="mechanum2_link_barrel6_trans">
    <type>transmission_interface/SimpleTransmission</type>
    <joint name="mechanum2_link_barrel6_joint">
      <hardwareInterface>hardware_interface/EffortJointInterface</hardwareInterface>
    </joint>
    <actuator name="mechanum2_link_barrel6_motor">
      <hardwareInterface>hardware_interface/EffortJointInterface</hardwareInterface>
      <mechanismReduction>1</mechanismReduction>
    </actuator>
  </transmission>
  <link name="mechanum2_link_barrel7">
    <visual>
      <geometry>
        <mesh filename="package://commissioning_robot/stl/ots-barrel-display_s.stl"/>
      </geometry>
      <origin rpy="0 0 0" xyz="0 0 0"/>
      <material name="blue"/>
    </visual>
    <inertial>
      <origin rpy="0 0 0" xyz="0 0 0"/>
      <mass value="0.020168905"/>
      <inertia ixx="9.115874e-07" ixy="0.0" ixz="0.0" iyx="0.0" iyy="3.5976895e-06" iyz="0.0" izx="0.0" izy="0.0" izz="3.5976895e-06"/>
    </inertial>
    <collision>
      <origin rpy="0 0 0" xyz="0 0 0"/>
      <geometry>
        <mesh filename="package://commissioning_robot/stl/ots-barrel-display_s.stl"/>
      </geometry>
    </collision>
  </link>
  <!-- <xacro:INSERT_GAZEBO_PHYSICS_UNIT  suffix="${suffix}" mu1="${1}" mu2="${1}" kp="${2e8}" kd="${0.1}" df="${0.03}" color="Gazebo/GreyGradientSky"/> -->
  <!-- <xacro:INSERT_GAZEBO_PHYSICS_UNIT  suffix="${suffix}" mu1="${1}" mu2="${1}" kp="${1}" kd="${1}" df="${0}" color="Gazebo/GreyGradientSky"/> -->
  <gazebo reference="mechanum2_link_barrel7">
    <material>Gazebo/GreyGradientSky</material>
    <dampingFactor>0.01</dampingFactor>
  </gazebo>
  <joint name="mechanum2_link_barrel7_joint" type="continuous">
    <parent link="mechanum2_link"/>
    <child link="mechanum2_link_barrel7"/>
    <origin rpy="4.1887902047863905 0.3926990816987245 0.6801747615878314" xyz="0 -0.020145000000000017 -0.034892163518475024"/>
    <axis xyz="1 0 0"/>
    <!-- <dynamics damping="1e-4"/> -->
    <!-- <limit effort="10000" velocity="10000"/> -->
    <!-- <safety_controller k_velocity="10" k_position="15" soft_lower_limit="-2.0" soft_upper_limit="0.5" /> -->
    <!-- <safety_controller k_velocity="10" k_position="15" /> -->
    <!-- <dynamics friction="10"/> -->
  </joint>
  <transmission name="mechanum2_link_barrel7_trans">
    <type>transmission_interface/SimpleTransmission</type>
    <joint name="mechanum2_link_barrel7_joint">
      <hardwareInterface>hardware_interface/EffortJointInterface</hardwareInterface>
    </joint>
    <actuator name="mechanum2_link_barrel7_motor">
      <hardwareInterface>hardware_interface/EffortJointInterface</hardwareInterface>
      <mechanismReduction>1</mechanismReduction>
    </actuator>
  </transmission>
  <link name="mechanum2_link_barrel8">
    <visual>
      <geometry>
        <mesh filename="package://commissioning_robot/stl/ots-barrel-display_s.stl"/>
      </geometry>
      <origin rpy="0 0 0" xyz="0 0 0"/>
      <material name="blue"/>
    </visual>
    <inertial>
      <origin rpy="0 0 0" xyz="0 0 0"/>
      <mass value="0.020168905"/>
      <inertia ixx="9.115874e-07" ixy="0.0" ixz="0.0" iyx="0.0" iyy="3.5976895e-06" iyz="0.0" izx="0.0" izy="0.0" izz="3.5976895e-06"/>
    </inertial>
    <collision>
      <origin rpy="0 0 0" xyz="0 0 0"/>
      <geometry>
        <mesh filename="package://commissioning_robot/stl/ots-barrel-display_s.stl"/>
      </geometry>
    </collision>
  </link>
  <!-- <xacro:INSERT_GAZEBO_PHYSICS_UNIT  suffix="${suffix}" mu1="${1}" mu2="${1}" kp="${2e8}" kd="${0.1}" df="${0.03}" color="Gazebo/GreyGradientSky"/> -->
  <!-- <xacro:INSERT_GAZEBO_PHYSICS_UNIT  suffix="${suffix}" mu1="${1}" mu2="${1}" kp="${1}" kd="${1}" df="${0}" color="Gazebo/GreyGradientSky"/> -->
  <gazebo reference="mechanum2_link_barrel8">
    <material>Gazebo/GreyGradientSky</material>
    <dampingFactor>0.01</dampingFactor>
  </gazebo>
  <joint name="mechanum2_link_barrel8_joint" type="continuous">
    <parent link="mechanum2_link"/>
    <child link="mechanum2_link_barrel8"/>
    <origin rpy="4.886921905584122 -0.13638295981692058 0.7734662005153561" xyz="0 0.006996285078200609 -0.039677904368861865"/>
    <axis xyz="1 0 0"/>
    <!-- <dynamics damping="1e-4"/> -->
    <!-- <limit effort="10000" velocity="10000"/> -->
    <!-- <safety_controller k_velocity="10" k_position="15" soft_lower_limit="-2.0" soft_upper_limit="0.5" /> -->
    <!-- <safety_controller k_velocity="10" k_position="15" /> -->
    <!-- <dynamics friction="10"/> -->
  </joint>
  <transmission name="mechanum2_link_barrel8_trans">
    <type>transmission_interface/SimpleTransmission</type>
    <joint name="mechanum2_link_barrel8_joint">
      <hardwareInterface>hardware_interface/EffortJointInterface</hardwareInterface>
    </joint>
    <actuator name="mechanum2_link_barrel8_motor">
      <hardwareInterface>hardware_interface/EffortJointInterface</hardwareInterface>
      <mechanismReduction>1</mechanismReduction>
    </actuator>
  </transmission>
  <link name="mechanum2_link_barrel9">
    <visual>
      <geometry>
        <mesh filename="package://commissioning_robot/stl/ots-barrel-display_s.stl"/>
      </geometry>
      <origin rpy="0 0 0" xyz="0 0 0"/>
      <material name="blue"/>
    </visual>
    <inertial>
      <origin rpy="0 0 0" xyz="0 0 0"/>
      <mass value="0.020168905"/>
      <inertia ixx="9.115874e-07" ixy="0.0" ixz="0.0" iyx="0.0" iyy="3.5976895e-06" iyz="0.0" izx="0.0" izy="0.0" izz="3.5976895e-06"/>
    </inertial>
    <collision>
      <origin rpy="0 0 0" xyz="0 0 0"/>
      <geometry>
        <mesh filename="package://commissioning_robot/stl/ots-barrel-display_s.stl"/>
      </geometry>
    </collision>
  </link>
  <!-- <xacro:INSERT_GAZEBO_PHYSICS_UNIT  suffix="${suffix}" mu1="${1}" mu2="${1}" kp="${2e8}" kd="${0.1}" df="${0.03}" color="Gazebo/GreyGradientSky"/> -->
  <!-- <xacro:INSERT_GAZEBO_PHYSICS_UNIT  suffix="${suffix}" mu1="${1}" mu2="${1}" kp="${1}" kd="${1}" df="${0}" color="Gazebo/GreyGradientSky"/> -->
  <gazebo reference="mechanum2_link_barrel9">
    <material>Gazebo/GreyGradientSky</material>
    <dampingFactor>0.01</dampingFactor>
  </gazebo>
  <joint name="mechanum2_link_barrel9_joint" type="continuous">
    <parent link="mechanum2_link"/>
    <child link="mechanum2_link_barrel9"/>
    <origin rpy="5.585053606381854 -0.6016498987064662 0.504844208102444" xyz="0 0.030863930613263615 -0.02589791279427068"/>
    <axis xyz="1 0 0"/>
    <!-- <dynamics damping="1e-4"/> -->
    <!-- <limit effort="10000" velocity="10000"/> -->
    <!-- <safety_controller k_velocity="10" k_position="15" soft_lower_limit="-2.0" soft_upper_limit="0.5" /> -->
    <!-- <safety_controller k_velocity="10" k_position="15" /> -->
    <!-- <dynamics friction="10"/> -->
  </joint>
  <transmission name="mechanum2_link_barrel9_trans">
    <type>transmission_interface/SimpleTransmission</type>
    <joint name="mechanum2_link_barrel9_joint">
      <hardwareInterface>hardware_interface/EffortJointInterface</hardwareInterface>
    </joint>
    <actuator name="mechanum2_link_barrel9_motor">
      <hardwareInterface>hardware_interface/EffortJointInterface</hardwareInterface>
      <mechanismReduction>1</mechanismReduction>
    </actuator>
  </transmission>
  <link name="mechanum3_link">
    <visual>
      <geometry>
        <mesh filename="package://commissioning_robot/stl/03-asm-mechanum-r.stl"/>
      </geometry>
      <origin rpy="0 0 0" xyz="0 0 0"/>
      <material name="blue"/>
    </visual>
    <inertial>
      <origin rpy="0 0 0" xyz="0 0 0"/>
      <mass value="0.2283143"/>
      <inertia ixx="0.00013964271" ixy="3.410723e-07" ixz="-4.0592855e-08" iyx="3.410723e-07" iyy="0.00014237371" iyz="-1.5000035e-08" izx="-4.0592855e-08" izy="1.5000035e-08" izz="0.00014228702"/>
    </inertial>
    <collision>
      <origin rpy="0 0 0" xyz="0 0 0"/>
      <geometry>
        <box size="0 0 0"/>
      </geometry>
    </collision>
  </link>
  <gazebo reference="mechanum3_link">
    <material>Gazebo/Grey</material>
    <mu1>1</mu1>
    <mu2>1</mu2>
    <kp>20000000000.0</kp>
    <kd>0.01</kd>
    <dampingFactor>0.01</dampingFactor>
    <!-- <minDepth>0.001</minDepth> -->
    <!-- <maxVel>0.01</maxVel> -->
    <!-- <turnGravityOff>true</turnGravityOff> -->
  </gazebo>
  <link name="mechanum3_link_barrel1">
    <visual>
      <geometry>
        <mesh filename="package://commissioning_robot/stl/ots-barrel-display_s.stl"/>
      </geometry>
      <origin rpy="0 0 0" xyz="0 0 0"/>
      <material name="blue"/>
    </visual>
    <inertial>
      <origin rpy="0 0 0" xyz="0 0 0"/>
      <mass value="0.020168905"/>
      <inertia ixx="9.115874e-07" ixy="0.0" ixz="0.0" iyx="0.0" iyy="3.5976895e-06" iyz="0.0" izx="0.0" izy="0.0" izz="3.5976895e-06"/>
    </inertial>
    <collision>
      <origin rpy="0 0 0" xyz="0 0 0"/>
      <geometry>
        <mesh filename="package://commissioning_robot/stl/ots-barrel-display_s.stl"/>
      </geometry>
    </collision>
  </link>
  <!-- <xacro:INSERT_GAZEBO_PHYSICS_UNIT  suffix="${suffix}" mu1="${1}" mu2="${1}" kp="${2e8}" kd="${0.1}" df="${0.03}" color="Gazebo/GreyGradientSky"/> -->
  <!-- <xacro:INSERT_GAZEBO_PHYSICS_UNIT  suffix="${suffix}" mu1="${1}" mu2="${1}" kp="${1}" kd="${1}" df="${0}" color="Gazebo/GreyGradientSky"/> -->
  <gazebo reference="mechanum3_link_barrel1">
    <material>Gazebo/GreyGradientSky</material>
    <dampingFactor>0.01</dampingFactor>
  </gazebo>
  <joint name="mechanum3_link_barrel1_joint" type="continuous">
    <parent link="mechanum3_link"/>
    <child link="mechanum3_link_barrel1"/>
    <origin rpy="0.0 0.7853981633974483 0.0" xyz="0 0.04029 0.0"/>
    <axis xyz="1 0 0"/>
    <!-- <dynamics damping="1e-4"/> -->
    <!-- <limit effort="10000" velocity="10000"/> -->
    <!-- <safety_controller k_velocity="10" k_position="15" soft_lower_limit="-2.0" soft_upper_limit="0.5" /> -->
    <!-- <safety_controller k_velocity="10" k_position="15" /> -->
    <!-- <dynamics friction="10"/> -->
  </joint>
  <transmission name="mechanum3_link_barrel1_trans">
    <type>transmission_interface/SimpleTransmission</type>
    <joint name="mechanum3_link_barrel1_joint">
      <hardwareInterface>hardware_interface/EffortJointInterface</hardwareInterface>
    </joint>
    <actuator name="mechanum3_link_barrel1_motor">
      <hardwareInterface>hardware_interface/EffortJointInterface</hardwareInterface>
      <mechanismReduction>1</mechanismReduction>
    </actuator>
  </transmission>
  <link name="mechanum3_link_barrel2">
    <visual>
      <geometry>
        <mesh filename="package://commissioning_robot/stl/ots-barrel-display_s.stl"/>
      </geometry>
      <origin rpy="0 0 0" xyz="0 0 0"/>
      <material name="blue"/>
    </visual>
    <inertial>
      <origin rpy="0 0 0" xyz="0 0 0"/>
      <mass value="0.020168905"/>
      <inertia ixx="9.115874e-07" ixy="0.0" ixz="0.0" iyx="0.0" iyy="3.5976895e-06" iyz="0.0" izx="0.0" izy="0.0" izz="3.5976895e-06"/>
    </inertial>
    <collision>
      <origin rpy="0 0 0" xyz="0 0 0"/>
      <geometry>
        <mesh filename="package://commissioning_robot/stl/ots-barrel-display_s.stl"/>
      </geometry>
    </collision>
  </link>
  <!-- <xacro:INSERT_GAZEBO_PHYSICS_UNIT  suffix="${suffix}" mu1="${1}" mu2="${1}" kp="${2e8}" kd="${0.1}" df="${0.03}" color="Gazebo/GreyGradientSky"/> -->
  <!-- <xacro:INSERT_GAZEBO_PHYSICS_UNIT  suffix="${suffix}" mu1="${1}" mu2="${1}" kp="${1}" kd="${1}" df="${0}" color="Gazebo/GreyGradientSky"/> -->
  <gazebo reference="mechanum3_link_barrel2">
    <material>Gazebo/GreyGradientSky</material>
    <dampingFactor>0.01</dampingFactor>
  </gazebo>
  <joint name="mechanum3_link_barrel2_joint" type="continuous">
    <parent link="mechanum3_link"/>
    <child link="mechanum3_link_barrel2"/>
    <origin rpy="0.6981317007977318 0.6016498987064663 0.5048442081024438" xyz="0 0.030863930613263625 0.025897912794270665"/>
    <axis xyz="1 0 0"/>
    <!-- <dynamics damping="1e-4"/> -->
    <!-- <limit effort="10000" velocity="10000"/> -->
    <!-- <safety_controller k_velocity="10" k_position="15" soft_lower_limit="-2.0" soft_upper_limit="0.5" /> -->
    <!-- <safety_controller k_velocity="10" k_position="15" /> -->
    <!-- <dynamics friction="10"/> -->
  </joint>
  <transmission name="mechanum3_link_barrel2_trans">
    <type>transmission_interface/SimpleTransmission</type>
    <joint name="mechanum3_link_barrel2_joint">
      <hardwareInterface>hardware_interface/EffortJointInterface</hardwareInterface>
    </joint>
    <actuator name="mechanum3_link_barrel2_motor">
      <hardwareInterface>hardware_interface/EffortJointInterface</hardwareInterface>
      <mechanismReduction>1</mechanismReduction>
    </actuator>
  </transmission>
  <link name="mechanum3_link_barrel3">
    <visual>
      <geometry>
        <mesh filename="package://commissioning_robot/stl/ots-barrel-display_s.stl"/>
      </geometry>
      <origin rpy="0 0 0" xyz="0 0 0"/>
      <material name="blue"/>
    </visual>
    <inertial>
      <origin rpy="0 0 0" xyz="0 0 0"/>
      <mass value="0.020168905"/>
      <inertia ixx="9.115874e-07" ixy="0.0" ixz="0.0" iyx="0.0" iyy="3.5976895e-06" iyz="0.0" izx="0.0" izy="0.0" izz="3.5976895e-06"/>
    </inertial>
    <collision>
      <origin rpy="0 0 0" xyz="0 0 0"/>
      <geometry>
        <mesh filename="package://commissioning_robot/stl/ots-barrel-display_s.stl"/>
      </geometry>
    </collision>
  </link>
  <!-- <xacro:INSERT_GAZEBO_PHYSICS_UNIT  suffix="${suffix}" mu1="${1}" mu2="${1}" kp="${2e8}" kd="${0.1}" df="${0.03}" color="Gazebo/GreyGradientSky"/> -->
  <!-- <xacro:INSERT_GAZEBO_PHYSICS_UNIT  suffix="${suffix}" mu1="${1}" mu2="${1}" kp="${1}" kd="${1}" df="${0}" color="Gazebo/GreyGradientSky"/> -->
  <gazebo reference="mechanum3_link_barrel3">
    <material>Gazebo/GreyGradientSky</material>
    <dampingFactor>0.01</dampingFactor>
  </gazebo>
  <joint name="mechanum3_link_barrel3_joint" type="continuous">
    <parent link="mechanum3_link"/>
    <child link="mechanum3_link_barrel3"/>
    <origin rpy="1.3962634015954636 0.13638295981692095 0.7734662005153561" xyz="0 0.006996285078200626 0.03967790436886186"/>
    <axis xyz="1 0 0"/>
    <!-- <dynamics damping="1e-4"/> -->
    <!-- <limit effort="10000" velocity="10000"/> -->
    <!-- <safety_controller k_velocity="10" k_position="15" soft_lower_limit="-2.0" soft_upper_limit="0.5" /> -->
    <!-- <safety_controller k_velocity="10" k_position="15" /> -->
    <!-- <dynamics friction="10"/> -->
  </joint>
  <transmission name="mechanum3_link_barrel3_trans">
    <type>transmission_interface/SimpleTransmission</type>
    <joint name="mechanum3_link_barrel3_joint">
      <hardwareInterface>hardware_interface/EffortJointInterface</hardwareInterface>
    </joint>
    <actuator name="mechanum3_link_barrel3_motor">
      <hardwareInterface>hardware_interface/EffortJointInterface</hardwareInterface>
      <mechanismReduction>1</mechanismReduction>
    </actuator>
  </transmission>
  <link name="mechanum3_link_barrel4">
    <visual>
      <geometry>
        <mesh filename="package://commissioning_robot/stl/ots-barrel-display_s.stl"/>
      </geometry>
      <origin rpy="0 0 0" xyz="0 0 0"/>
      <material name="blue"/>
    </visual>
    <inertial>
      <origin rpy="0 0 0" xyz="0 0 0"/>
      <mass value="0.020168905"/>
      <inertia ixx="9.115874e-07" ixy="0.0" ixz="0.0" iyx="0.0" iyy="3.5976895e-06" iyz="0.0" izx="0.0" izy="0.0" izz="3.5976895e-06"/>
    </inertial>
    <collision>
      <origin rpy="0 0 0" xyz="0 0 0"/>
      <geometry>
        <mesh filename="package://commissioning_robot/stl/ots-barrel-display_s.stl"/>
      </geometry>
    </collision>
  </link>
  <!-- <xacro:INSERT_GAZEBO_PHYSICS_UNIT  suffix="${suffix}" mu1="${1}" mu2="${1}" kp="${2e8}" kd="${0.1}" df="${0.03}" color="Gazebo/GreyGradientSky"/> -->
  <!-- <xacro:INSERT_GAZEBO_PHYSICS_UNIT  suffix="${suffix}" mu1="${1}" mu2="${1}" kp="${1}" kd="${1}" df="${0}" color="Gazebo/GreyGradientSky"/> -->
  <gazebo reference="mechanum3_link_barrel4">
    <material>Gazebo/GreyGradientSky</material>
    <dampingFactor>0.01</dampingFactor>
  </gazebo>
  <joint name="mechanum3_link_barrel4_joint" type="continuous">
    <parent link="mechanum3_link"/>
    <child link="mechanum3_link_barrel4"/>
    <origin rpy="2.0943951023931953 -0.392699081698724 0.6801747615878317" xyz="0 -0.02014499999999999 0.03489216351847504"/>
    <axis xyz="1 0 0"/>
    <!-- <dynamics damping="1e-4"/> -->
    <!-- <limit effort="10000" velocity="10000"/> -->
    <!-- <safety_controller k_velocity="10" k_position="15" soft_lower_limit="-2.0" soft_upper_limit="0.5" /> -->
    <!-- <safety_controller k_velocity="10" k_position="15" /> -->
    <!-- <dynamics friction="10"/> -->
  </joint>
  <transmission name="mechanum3_link_barrel4_trans">
    <type>transmission_interface/SimpleTransmission</type>
    <joint name="mechanum3_link_barrel4_joint">
      <hardwareInterface>hardware_interface/EffortJointInterface</hardwareInterface>
    </joint>
    <actuator name="mechanum3_link_barrel4_motor">
      <hardwareInterface>hardware_interface/EffortJointInterface</hardwareInterface>
      <mechanismReduction>1</mechanismReduction>
    </actuator>
  </transmission>
  <link name="mechanum3_link_barrel5">
    <visual>
      <geometry>
        <mesh filename="package://commissioning_robot/stl/ots-barrel-display_s.stl"/>
      </geometry>
      <origin rpy="0 0 0" xyz="0 0 0"/>
      <material name="blue"/>
    </visual>
    <inertial>
      <origin rpy="0 0 0" xyz="0 0 0"/>
      <mass value="0.020168905"/>
      <inertia ixx="9.115874e-07" ixy="0.0" ixz="0.0" iyx="0.0" iyy="3.5976895e-06" iyz="0.0" izx="0.0" izy="0.0" izz="3.5976895e-06"/>
    </inertial>
    <collision>
      <origin rpy="0 0 0" xyz="0 0 0"/>
      <geometry>
        <mesh filename="package://commissioning_robot/stl/ots-barrel-display_s.stl"/>
      </geometry>
    </collision>
  </link>
  <!-- <xacro:INSERT_GAZEBO_PHYSICS_UNIT  suffix="${suffix}" mu1="${1}" mu2="${1}" kp="${2e8}" kd="${0.1}" df="${0.03}" color="Gazebo/GreyGradientSky"/> -->
  <!-- <xacro:INSERT_GAZEBO_PHYSICS_UNIT  suffix="${suffix}" mu1="${1}" mu2="${1}" kp="${1}" kd="${1}" df="${0}" color="Gazebo/GreyGradientSky"/> -->
  <gazebo reference="mechanum3_link_barrel5">
    <material>Gazebo/GreyGradientSky</material>
    <dampingFactor>0.01</dampingFactor>
  </gazebo>
  <joint name="mechanum3_link_barrel5_joint" type="continuous">
    <parent link="mechanum3_link"/>
    <child link="mechanum3_link_barrel5"/>
    <origin rpy="2.792526803190927 -0.7380328585233872 0.26862199241291235" xyz="0 -0.03786021569146424 0.0137799915745912"/>
    <axis xyz="1 0 0"/>
    <!-- <dynamics damping="1e-4"/> -->
    <!-- <limit effort="10000" velocity="10000"/> -->
    <!-- <safety_controller k_velocity="10" k_position="15" soft_lower_limit="-2.0" soft_upper_limit="0.5" /> -->
    <!-- <safety_controller k_velocity="10" k_position="15" /> -->
    <!-- <dynamics friction="10"/> -->
  </joint>
  <transmission name="mechanum3_link_barrel5_trans">
    <type>transmission_interface/SimpleTransmission</type>
    <joint name="mechanum3_link_barrel5_joint">
      <hardwareInterface>hardware_interface/EffortJointInterface</hardwareInterface>
    </joint>
    <actuator name="mechanum3_link_barrel5_motor">
      <hardwareInterface>hardware_interface/EffortJointInterface</hardwareInterface>
      <mechanismReduction>1</mechanismReduction>
    </actuator>
  </transmission>
  <link name="mechanum3_link_barrel6">
    <visual>
      <geometry>
        <mesh filename="package://commissioning_robot/stl/ots-barrel-display_s.stl"/>
      </geometry>
      <origin rpy="0 0 0" xyz="0 0 0"/>
      <material name="blue"/>
    </visual>
    <inertial>
      <origin rpy="0 0 0" xyz="0 0 0"/>
      <mass value="0.020168905"/>
      <inertia ixx="9.115874e-07" ixy="0.0" ixz="0.0" iyx="0.0" iyy="3.5976895e-06" iyz="0.0" izx="0.0" izy="0.0" izz="3.5976895e-06"/>
    </inertial>
    <collision>
      <origin rpy="0 0 0" xyz="0 0 0"/>
      <geometry>
        <mesh filename="package://commissioning_robot/stl/ots-barrel-display_s.stl"/>
      </geometry>
    </collision>
  </link>
  <!-- <xacro:INSERT_GAZEBO_PHYSICS_UNIT  suffix="${suffix}" mu1="${1}" mu2="${1}" kp="${2e8}" kd="${0.1}" df="${0.03}" color="Gazebo/GreyGradientSky"/> -->
  <!-- <xacro:INSERT_GAZEBO_PHYSICS_UNIT  suffix="${suffix}" mu1="${1}" mu2="${1}" kp="${1}" kd="${1}" df="${0}" color="Gazebo/GreyGradientSky"/> -->
  <gazebo reference="mechanum3_link_barrel6">
    <material>Gazebo/GreyGradientSky</material>
    <dampingFactor>0.01</dampingFactor>
  </gazebo>
  <joint name="mechanum3_link_barrel6_joint" type="continuous">
    <parent link="mechanum3_link"/>
    <child link="mechanum3_link_barrel6"/>
    <origin rpy="3.490658503988659 -0.7380328585233873 -0.2686219924129122" xyz="0 -0.03786021569146425 -0.01377999157459119"/>
    <axis xyz="1 0 0"/>
    <!-- <dynamics damping="1e-4"/> -->
    <!-- <limit effort="10000" velocity="10000"/> -->
    <!-- <safety_controller k_velocity="10" k_position="15" soft_lower_limit="-2.0" soft_upper_limit="0.5" /> -->
    <!-- <safety_controller k_velocity="10" k_position="15" /> -->
    <!-- <dynamics friction="10"/> -->
  </joint>
  <transmission name="mechanum3_link_barrel6_trans">
    <type>transmission_interface/SimpleTransmission</type>
    <joint name="mechanum3_link_barrel6_joint">
      <hardwareInterface>hardware_interface/EffortJointInterface</hardwareInterface>
    </joint>
    <actuator name="mechanum3_link_barrel6_motor">
      <hardwareInterface>hardware_interface/EffortJointInterface</hardwareInterface>
      <mechanismReduction>1</mechanismReduction>
    </actuator>
  </transmission>
  <link name="mechanum3_link_barrel7">
    <visual>
      <geometry>
        <mesh filename="package://commissioning_robot/stl/ots-barrel-display_s.stl"/>
      </geometry>
      <origin rpy="0 0 0" xyz="0 0 0"/>
      <material name="blue"/>
    </visual>
    <inertial>
      <origin rpy="0 0 0" xyz="0 0 0"/>
      <mass value="0.020168905"/>
      <inertia ixx="9.115874e-07" ixy="0.0" ixz="0.0" iyx="0.0" iyy="3.5976895e-06" iyz="0.0" izx="0.0" izy="0.0" izz="3.5976895e-06"/>
    </inertial>
    <collision>
      <origin rpy="0 0 0" xyz="0 0 0"/>
      <geometry>
        <mesh filename="package://commissioning_robot/stl/ots-barrel-display_s.stl"/>
      </geometry>
    </collision>
  </link>
  <!-- <xacro:INSERT_GAZEBO_PHYSICS_UNIT  suffix="${suffix}" mu1="${1}" mu2="${1}" kp="${2e8}" kd="${0.1}" df="${0.03}" color="Gazebo/GreyGradientSky"/> -->
  <!-- <xacro:INSERT_GAZEBO_PHYSICS_UNIT  suffix="${suffix}" mu1="${1}" mu2="${1}" kp="${1}" kd="${1}" df="${0}" color="Gazebo/GreyGradientSky"/> -->
  <gazebo reference="mechanum3_link_barrel7">
    <material>Gazebo/GreyGradientSky</material>
    <dampingFactor>0.01</dampingFactor>
  </gazebo>
  <joint name="mechanum3_link_barrel7_joint" type="continuous">
    <parent link="mechanum3_link"/>
    <child link="mechanum3_link_barrel7"/>
    <origin rpy="4.1887902047863905 -0.3926990816987245 -0.6801747615878314" xyz="0 -0.020145000000000017 -0.034892163518475024"/>
    <axis xyz="1 0 0"/>
    <!-- <dynamics damping="1e-4"/> -->
    <!-- <limit effort="10000" velocity="10000"/> -->
    <!-- <safety_controller k_velocity="10" k_position="15" soft_lower_limit="-2.0" soft_upper_limit="0.5" /> -->
    <!-- <safety_controller k_velocity="10" k_position="15" /> -->
    <!-- <dynamics friction="10"/> -->
  </joint>
  <transmission name="mechanum3_link_barrel7_trans">
    <type>transmission_interface/SimpleTransmission</type>
    <joint name="mechanum3_link_barrel7_joint">
      <hardwareInterface>hardware_interface/EffortJointInterface</hardwareInterface>
    </joint>
    <actuator name="mechanum3_link_barrel7_motor">
      <hardwareInterface>hardware_interface/EffortJointInterface</hardwareInterface>
      <mechanismReduction>1</mechanismReduction>
    </actuator>
  </transmission>
  <link name="mechanum3_link_barrel8">
    <visual>
      <geometry>
        <mesh filename="package://commissioning_robot/stl/ots-barrel-display_s.stl"/>
      </geometry>
      <origin rpy="0 0 0" xyz="0 0 0"/>
      <material name="blue"/>
    </visual>
    <inertial>
      <origin rpy="0 0 0" xyz="0 0 0"/>
      <mass value="0.020168905"/>
      <inertia ixx="9.115874e-07" ixy="0.0" ixz="0.0" iyx="0.0" iyy="3.5976895e-06" iyz="0.0" izx="0.0" izy="0.0" izz="3.5976895e-06"/>
    </inertial>
    <collision>
      <origin rpy="0 0 0" xyz="0 0 0"/>
      <geometry>
        <mesh filename="package://commissioning_robot/stl/ots-barrel-display_s.stl"/>
      </geometry>
    </collision>
  </link>
  <!-- <xacro:INSERT_GAZEBO_PHYSICS_UNIT  suffix="${suffix}" mu1="${1}" mu2="${1}" kp="${2e8}" kd="${0.1}" df="${0.03}" color="Gazebo/GreyGradientSky"/> -->
  <!-- <xacro:INSERT_GAZEBO_PHYSICS_UNIT  suffix="${suffix}" mu1="${1}" mu2="${1}" kp="${1}" kd="${1}" df="${0}" color="Gazebo/GreyGradientSky"/> -->
  <gazebo reference="mechanum3_link_barrel8">
    <material>Gazebo/GreyGradientSky</material>
    <dampingFactor>0.01</dampingFactor>
  </gazebo>
  <joint name="mechanum3_link_barrel8_joint" type="continuous">
    <parent link="mechanum3_link"/>
    <child link="mechanum3_link_barrel8"/>
    <origin rpy="4.886921905584122 0.13638295981692058 -0.7734662005153561" xyz="0 0.006996285078200609 -0.039677904368861865"/>
    <axis xyz="1 0 0"/>
    <!-- <dynamics damping="1e-4"/> -->
    <!-- <limit effort="10000" velocity="10000"/> -->
    <!-- <safety_controller k_velocity="10" k_position="15" soft_lower_limit="-2.0" soft_upper_limit="0.5" /> -->
    <!-- <safety_controller k_velocity="10" k_position="15" /> -->
    <!-- <dynamics friction="10"/> -->
  </joint>
  <transmission name="mechanum3_link_barrel8_trans">
    <type>transmission_interface/SimpleTransmission</type>
    <joint name="mechanum3_link_barrel8_joint">
      <hardwareInterface>hardware_interface/EffortJointInterface</hardwareInterface>
    </joint>
    <actuator name="mechanum3_link_barrel8_motor">
      <hardwareInterface>hardware_interface/EffortJointInterface</hardwareInterface>
      <mechanismReduction>1</mechanismReduction>
    </actuator>
  </transmission>
  <link name="mechanum3_link_barrel9">
    <visual>
      <geometry>
        <mesh filename="package://commissioning_robot/stl/ots-barrel-display_s.stl"/>
      </geometry>
      <origin rpy="0 0 0" xyz="0 0 0"/>
      <material name="blue"/>
    </visual>
    <inertial>
      <origin rpy="0 0 0" xyz="0 0 0"/>
      <mass value="0.020168905"/>
      <inertia ixx="9.115874e-07" ixy="0.0" ixz="0.0" iyx="0.0" iyy="3.5976895e-06" iyz="0.0" izx="0.0" izy="0.0" izz="3.5976895e-06"/>
    </inertial>
    <collision>
      <origin rpy="0 0 0" xyz="0 0 0"/>
      <geometry>
        <mesh filename="package://commissioning_robot/stl/ots-barrel-display_s.stl"/>
      </geometry>
    </collision>
  </link>
  <!-- <xacro:INSERT_GAZEBO_PHYSICS_UNIT  suffix="${suffix}" mu1="${1}" mu2="${1}" kp="${2e8}" kd="${0.1}" df="${0.03}" color="Gazebo/GreyGradientSky"/> -->
  <!-- <xacro:INSERT_GAZEBO_PHYSICS_UNIT  suffix="${suffix}" mu1="${1}" mu2="${1}" kp="${1}" kd="${1}" df="${0}" color="Gazebo/GreyGradientSky"/> -->
  <gazebo reference="mechanum3_link_barrel9">
    <material>Gazebo/GreyGradientSky</material>
    <dampingFactor>0.01</dampingFactor>
  </gazebo>
  <joint name="mechanum3_link_barrel9_joint" type="continuous">
    <parent link="mechanum3_link"/>
    <child link="mechanum3_link_barrel9"/>
    <origin rpy="5.585053606381854 0.6016498987064662 -0.504844208102444" xyz="0 0.030863930613263615 -0.02589791279427068"/>
    <axis xyz="1 0 0"/>
    <!-- <dynamics damping="1e-4"/> -->
    <!-- <limit effort="10000" velocity="10000"/> -->
    <!-- <safety_controller k_velocity="10" k_position="15" soft_lower_limit="-2.0" soft_upper_limit="0.5" /> -->
    <!-- <safety_controller k_velocity="10" k_position="15" /> -->
    <!-- <dynamics friction="10"/> -->
  </joint>
  <transmission name="mechanum3_link_barrel9_trans">
    <type>transmission_interface/SimpleTransmission</type>
    <joint name="mechanum3_link_barrel9_joint">
      <hardwareInterface>hardware_interface/EffortJointInterface</hardwareInterface>
    </joint>
    <actuator name="mechanum3_link_barrel9_motor">
      <hardwareInterface>hardware_interface/EffortJointInterface</hardwareInterface>
      <mechanismReduction>1</mechanismReduction>
    </actuator>
  </transmission>
  <link name="mechanum4_link">
    <visual>
      <geometry>
        <mesh filename="package://commissioning_robot/stl/03-asm-mechanum-l.stl"/>
      </geometry>
      <origin rpy="0.3490658503988659 0 3.141592653589793" xyz="0 0 0"/>
      <material name="blue"/>
    </visual>
    <inertial>
      <origin rpy="0 0 0" xyz="0 0 0"/>
      <mass value="0.2283143"/>
      <inertia ixx="0.00013964271" ixy="-2.4376656e-7" ixz="-4.0742095e-08" iyx="-2.4376656e-07" iyy="0.00014237359" iyz="1.5005847e-08" izx="-4.0742095e-08" izy="1.5005847e-08" izz="0.00014228689"/>
    </inertial>
    <collision>
      <origin rpy="0.3490658503988659 0 3.141592653589793" xyz="0 0 0"/>
      <geometry>
        <box size="0 0 0"/>
      </geometry>
    </collision>
  </link>
  <gazebo reference="mechanum4_link">
    <material>Gazebo/Grey</material>
    <mu1>1</mu1>
    <mu2>1</mu2>
    <kp>20000000000.0</kp>
    <kd>0.01</kd>
    <dampingFactor>0.01</dampingFactor>
    <!-- <minDepth>0.001</minDepth> -->
    <!-- <maxVel>0.01</maxVel> -->
    <!-- <turnGravityOff>true</turnGravityOff> -->
  </gazebo>
  <link name="mechanum4_link_barrel1">
    <visual>
      <geometry>
        <mesh filename="package://commissioning_robot/stl/ots-barrel-display_s.stl"/>
      </geometry>
      <origin rpy="0 0 0" xyz="0 0 0"/>
      <material name="blue"/>
    </visual>
    <inertial>
      <origin rpy="0 0 0" xyz="0 0 0"/>
      <mass value="0.020168905"/>
      <inertia ixx="9.115874e-07" ixy="0.0" ixz="0.0" iyx="0.0" iyy="3.5976895e-06" iyz="0.0" izx="0.0" izy="0.0" izz="3.5976895e-06"/>
    </inertial>
    <collision>
      <origin rpy="0 0 0" xyz="0 0 0"/>
      <geometry>
        <mesh filename="package://commissioning_robot/stl/ots-barrel-display_s.stl"/>
      </geometry>
    </collision>
  </link>
  <!-- <xacro:INSERT_GAZEBO_PHYSICS_UNIT  suffix="${suffix}" mu1="${1}" mu2="${1}" kp="${2e8}" kd="${0.1}" df="${0.03}" color="Gazebo/GreyGradientSky"/> -->
  <!-- <xacro:INSERT_GAZEBO_PHYSICS_UNIT  suffix="${suffix}" mu1="${1}" mu2="${1}" kp="${1}" kd="${1}" df="${0}" color="Gazebo/GreyGradientSky"/> -->
  <gazebo reference="mechanum4_link_barrel1">
    <material>Gazebo/GreyGradientSky</material>
    <dampingFactor>0.01</dampingFactor>
  </gazebo>
  <joint name="mechanum4_link_barrel1_joint" type="continuous">
    <parent link="mechanum4_link"/>
    <child link="mechanum4_link_barrel1"/>
    <origin rpy="0.0 -0.7853981633974483 -0.0" xyz="0 0.04029 0.0"/>
    <axis xyz="1 0 0"/>
    <!-- <dynamics damping="1e-4"/> -->
    <!-- <limit effort="10000" velocity="10000"/> -->
    <!-- <safety_controller k_velocity="10" k_position="15" soft_lower_limit="-2.0" soft_upper_limit="0.5" /> -->
    <!-- <safety_controller k_velocity="10" k_position="15" /> -->
    <!-- <dynamics friction="10"/> -->
  </joint>
  <transmission name="mechanum4_link_barrel1_trans">
    <type>transmission_interface/SimpleTransmission</type>
    <joint name="mechanum4_link_barrel1_joint">
      <hardwareInterface>hardware_interface/EffortJointInterface</hardwareInterface>
    </joint>
    <actuator name="mechanum4_link_barrel1_motor">
      <hardwareInterface>hardware_interface/EffortJointInterface</hardwareInterface>
      <mechanismReduction>1</mechanismReduction>
    </actuator>
  </transmission>
  <link name="mechanum4_link_barrel2">
    <visual>
      <geometry>
        <mesh filename="package://commissioning_robot/stl/ots-barrel-display_s.stl"/>
      </geometry>
      <origin rpy="0 0 0" xyz="0 0 0"/>
      <material name="blue"/>
    </visual>
    <inertial>
      <origin rpy="0 0 0" xyz="0 0 0"/>
      <mass value="0.020168905"/>
      <inertia ixx="9.115874e-07" ixy="0.0" ixz="0.0" iyx="0.0" iyy="3.5976895e-06" iyz="0.0" izx="0.0" izy="0.0" izz="3.5976895e-06"/>
    </inertial>
    <collision>
      <origin rpy="0 0 0" xyz="0 0 0"/>
      <geometry>
        <mesh filename="package://commissioning_robot/stl/ots-barrel-display_s.stl"/>
      </geometry>
    </collision>
  </link>
  <!-- <xacro:INSERT_GAZEBO_PHYSICS_UNIT  suffix="${suffix}" mu1="${1}" mu2="${1}" kp="${2e8}" kd="${0.1}" df="${0.03}" color="Gazebo/GreyGradientSky"/> -->
  <!-- <xacro:INSERT_GAZEBO_PHYSICS_UNIT  suffix="${suffix}" mu1="${1}" mu2="${1}" kp="${1}" kd="${1}" df="${0}" color="Gazebo/GreyGradientSky"/> -->
  <gazebo reference="mechanum4_link_barrel2">
    <material>Gazebo/GreyGradientSky</material>
    <dampingFactor>0.01</dampingFactor>
  </gazebo>
  <joint name="mechanum4_link_barrel2_joint" type="continuous">
    <parent link="mechanum4_link"/>
    <child link="mechanum4_link_barrel2"/>
    <origin rpy="0.6981317007977318 -0.6016498987064663 -0.5048442081024438" xyz="0 0.030863930613263625 0.025897912794270665"/>
    <axis xyz="1 0 0"/>
    <!-- <dynamics damping="1e-4"/> -->
    <!-- <limit effort="10000" velocity="10000"/> -->
    <!-- <safety_controller k_velocity="10" k_position="15" soft_lower_limit="-2.0" soft_upper_limit="0.5" /> -->
    <!-- <safety_controller k_velocity="10" k_position="15" /> -->
    <!-- <dynamics friction="10"/> -->
  </joint>
  <transmission name="mechanum4_link_barrel2_trans">
    <type>transmission_interface/SimpleTransmission</type>
    <joint name="mechanum4_link_barrel2_joint">
      <hardwareInterface>hardware_interface/EffortJointInterface</hardwareInterface>
    </joint>
    <actuator name="mechanum4_link_barrel2_motor">
      <hardwareInterface>hardware_interface/EffortJointInterface</hardwareInterface>
      <mechanismReduction>1</mechanismReduction>
    </actuator>
  </transmission>
  <link name="mechanum4_link_barrel3">
    <visual>
      <geometry>
        <mesh filename="package://commissioning_robot/stl/ots-barrel-display_s.stl"/>
      </geometry>
      <origin rpy="0 0 0" xyz="0 0 0"/>
      <material name="blue"/>
    </visual>
    <inertial>
      <origin rpy="0 0 0" xyz="0 0 0"/>
      <mass value="0.020168905"/>
      <inertia ixx="9.115874e-07" ixy="0.0" ixz="0.0" iyx="0.0" iyy="3.5976895e-06" iyz="0.0" izx="0.0" izy="0.0" izz="3.5976895e-06"/>
    </inertial>
    <collision>
      <origin rpy="0 0 0" xyz="0 0 0"/>
      <geometry>
        <mesh filename="package://commissioning_robot/stl/ots-barrel-display_s.stl"/>
      </geometry>
    </collision>
  </link>
  <!-- <xacro:INSERT_GAZEBO_PHYSICS_UNIT  suffix="${suffix}" mu1="${1}" mu2="${1}" kp="${2e8}" kd="${0.1}" df="${0.03}" color="Gazebo/GreyGradientSky"/> -->
  <!-- <xacro:INSERT_GAZEBO_PHYSICS_UNIT  suffix="${suffix}" mu1="${1}" mu2="${1}" kp="${1}" kd="${1}" df="${0}" color="Gazebo/GreyGradientSky"/> -->
  <gazebo reference="mechanum4_link_barrel3">
    <material>Gazebo/GreyGradientSky</material>
    <dampingFactor>0.01</dampingFactor>
  </gazebo>
  <joint name="mechanum4_link_barrel3_joint" type="continuous">
    <parent link="mechanum4_link"/>
    <child link="mechanum4_link_barrel3"/>
    <origin rpy="1.3962634015954636 -0.13638295981692095 -0.7734662005153561" xyz="0 0.006996285078200626 0.03967790436886186"/>
    <axis xyz="1 0 0"/>
    <!-- <dynamics damping="1e-4"/> -->
    <!-- <limit effort="10000" velocity="10000"/> -->
    <!-- <safety_controller k_velocity="10" k_position="15" soft_lower_limit="-2.0" soft_upper_limit="0.5" /> -->
    <!-- <safety_controller k_velocity="10" k_position="15" /> -->
    <!-- <dynamics friction="10"/> -->
  </joint>
  <transmission name="mechanum4_link_barrel3_trans">
    <type>transmission_interface/SimpleTransmission</type>
    <joint name="mechanum4_link_barrel3_joint">
      <hardwareInterface>hardware_interface/EffortJointInterface</hardwareInterface>
    </joint>
    <actuator name="mechanum4_link_barrel3_motor">
      <hardwareInterface>hardware_interface/EffortJointInterface</hardwareInterface>
      <mechanismReduction>1</mechanismReduction>
    </actuator>
  </transmission>
  <link name="mechanum4_link_barrel4">
    <visual>
      <geometry>
        <mesh filename="package://commissioning_robot/stl/ots-barrel-display_s.stl"/>
      </geometry>
      <origin rpy="0 0 0" xyz="0 0 0"/>
      <material name="blue"/>
    </visual>
    <inertial>
      <origin rpy="0 0 0" xyz="0 0 0"/>
      <mass value="0.020168905"/>
      <inertia ixx="9.115874e-07" ixy="0.0" ixz="0.0" iyx="0.0" iyy="3.5976895e-06" iyz="0.0" izx="0.0" izy="0.0" izz="3.5976895e-06"/>
    </inertial>
    <collision>
      <origin rpy="0 0 0" xyz="0 0 0"/>
      <geometry>
        <mesh filename="package://commissioning_robot/stl/ots-barrel-display_s.stl"/>
      </geometry>
    </collision>
  </link>
  <!-- <xacro:INSERT_GAZEBO_PHYSICS_UNIT  suffix="${suffix}" mu1="${1}" mu2="${1}" kp="${2e8}" kd="${0.1}" df="${0.03}" color="Gazebo/GreyGradientSky"/> -->
  <!-- <xacro:INSERT_GAZEBO_PHYSICS_UNIT  suffix="${suffix}" mu1="${1}" mu2="${1}" kp="${1}" kd="${1}" df="${0}" color="Gazebo/GreyGradientSky"/> -->
  <gazebo reference="mechanum4_link_barrel4">
    <material>Gazebo/GreyGradientSky</material>
    <dampingFactor>0.01</dampingFactor>
  </gazebo>
  <joint name="mechanum4_link_barrel4_joint" type="continuous">
    <parent link="mechanum4_link"/>
    <child link="mechanum4_link_barrel4"/>
    <origin rpy="2.0943951023931953 0.392699081698724 -0.6801747615878317" xyz="0 -0.02014499999999999 0.03489216351847504"/>
    <axis xyz="1 0 0"/>
    <!-- <dynamics damping="1e-4"/> -->
    <!-- <limit effort="10000" velocity="10000"/> -->
    <!-- <safety_controller k_velocity="10" k_position="15" soft_lower_limit="-2.0" soft_upper_limit="0.5" /> -->
    <!-- <safety_controller k_velocity="10" k_position="15" /> -->
    <!-- <dynamics friction="10"/> -->
  </joint>
  <transmission name="mechanum4_link_barrel4_trans">
    <type>transmission_interface/SimpleTransmission</type>
    <joint name="mechanum4_link_barrel4_joint">
      <hardwareInterface>hardware_interface/EffortJointInterface</hardwareInterface>
    </joint>
    <actuator name="mechanum4_link_barrel4_motor">
      <hardwareInterface>hardware_interface/EffortJointInterface</hardwareInterface>
      <mechanismReduction>1</mechanismReduction>
    </actuator>
  </transmission>
  <link name="mechanum4_link_barrel5">
    <visual>
      <geometry>
        <mesh filename="package://commissioning_robot/stl/ots-barrel-display_s.stl"/>
      </geometry>
      <origin rpy="0 0 0" xyz="0 0 0"/>
      <material name="blue"/>
    </visual>
    <inertial>
      <origin rpy="0 0 0" xyz="0 0 0"/>
      <mass value="0.020168905"/>
      <inertia ixx="9.115874e-07" ixy="0.0" ixz="0.0" iyx="0.0" iyy="3.5976895e-06" iyz="0.0" izx="0.0" izy="0.0" izz="3.5976895e-06"/>
    </inertial>
    <collision>
      <origin rpy="0 0 0" xyz="0 0 0"/>
      <geometry>
        <mesh filename="package://commissioning_robot/stl/ots-barrel-display_s.stl"/>
      </geometry>
    </collision>
  </link>
  <!-- <xacro:INSERT_GAZEBO_PHYSICS_UNIT  suffix="${suffix}" mu1="${1}" mu2="${1}" kp="${2e8}" kd="${0.1}" df="${0.03}" color="Gazebo/GreyGradientSky"/> -->
  <!-- <xacro:INSERT_GAZEBO_PHYSICS_UNIT  suffix="${suffix}" mu1="${1}" mu2="${1}" kp="${1}" kd="${1}" df="${0}" color="Gazebo/GreyGradientSky"/> -->
  <gazebo reference="mechanum4_link_barrel5">
    <material>Gazebo/GreyGradientSky</material>
    <dampingFactor>0.01</dampingFactor>
  </gazebo>
  <joint name="mechanum4_link_barrel5_joint" type="continuous">
    <parent link="mechanum4_link"/>
    <child link="mechanum4_link_barrel5"/>
    <origin rpy="2.792526803190927 0.7380328585233872 -0.26862199241291235" xyz="0 -0.03786021569146424 0.0137799915745912"/>
    <axis xyz="1 0 0"/>
    <!-- <dynamics damping="1e-4"/> -->
    <!-- <limit effort="10000" velocity="10000"/> -->
    <!-- <safety_controller k_velocity="10" k_position="15" soft_lower_limit="-2.0" soft_upper_limit="0.5" /> -->
    <!-- <safety_controller k_velocity="10" k_position="15" /> -->
    <!-- <dynamics friction="10"/> -->
  </joint>
  <transmission name="mechanum4_link_barrel5_trans">
    <type>transmission_interface/SimpleTransmission</type>
    <joint name="mechanum4_link_barrel5_joint">
      <hardwareInterface>hardware_interface/EffortJointInterface</hardwareInterface>
    </joint>
    <actuator name="mechanum4_link_barrel5_motor">
      <hardwareInterface>hardware_interface/EffortJointInterface</hardwareInterface>
      <mechanismReduction>1</mechanismReduction>
    </actuator>
  </transmission>
  <link name="mechanum4_link_barrel6">
    <visual>
      <geometry>
        <mesh filename="package://commissioning_robot/stl/ots-barrel-display_s.stl"/>
      </geometry>
      <origin rpy="0 0 0" xyz="0 0 0"/>
      <material name="blue"/>
    </visual>
    <inertial>
      <origin rpy="0 0 0" xyz="0 0 0"/>
      <mass value="0.020168905"/>
      <inertia ixx="9.115874e-07" ixy="0.0" ixz="0.0" iyx="0.0" iyy="3.5976895e-06" iyz="0.0" izx="0.0" izy="0.0" izz="3.5976895e-06"/>
    </inertial>
    <collision>
      <origin rpy="0 0 0" xyz="0 0 0"/>
      <geometry>
        <mesh filename="package://commissioning_robot/stl/ots-barrel-display_s.stl"/>
      </geometry>
    </collision>
  </link>
  <!-- <xacro:INSERT_GAZEBO_PHYSICS_UNIT  suffix="${suffix}" mu1="${1}" mu2="${1}" kp="${2e8}" kd="${0.1}" df="${0.03}" color="Gazebo/GreyGradientSky"/> -->
  <!-- <xacro:INSERT_GAZEBO_PHYSICS_UNIT  suffix="${suffix}" mu1="${1}" mu2="${1}" kp="${1}" kd="${1}" df="${0}" color="Gazebo/GreyGradientSky"/> -->
  <gazebo reference="mechanum4_link_barrel6">
    <material>Gazebo/GreyGradientSky</material>
    <dampingFactor>0.01</dampingFactor>
  </gazebo>
  <joint name="mechanum4_link_barrel6_joint" type="continuous">
    <parent link="mechanum4_link"/>
    <child link="mechanum4_link_barrel6"/>
    <origin rpy="3.490658503988659 0.7380328585233873 0.2686219924129122" xyz="0 -0.03786021569146425 -0.01377999157459119"/>
    <axis xyz="1 0 0"/>
    <!-- <dynamics damping="1e-4"/> -->
    <!-- <limit effort="10000" velocity="10000"/> -->
    <!-- <safety_controller k_velocity="10" k_position="15" soft_lower_limit="-2.0" soft_upper_limit="0.5" /> -->
    <!-- <safety_controller k_velocity="10" k_position="15" /> -->
    <!-- <dynamics friction="10"/> -->
  </joint>
  <transmission name="mechanum4_link_barrel6_trans">
    <type>transmission_interface/SimpleTransmission</type>
    <joint name="mechanum4_link_barrel6_joint">
      <hardwareInterface>hardware_interface/EffortJointInterface</hardwareInterface>
    </joint>
    <actuator name="mechanum4_link_barrel6_motor">
      <hardwareInterface>hardware_interface/EffortJointInterface</hardwareInterface>
      <mechanismReduction>1</mechanismReduction>
    </actuator>
  </transmission>
  <link name="mechanum4_link_barrel7">
    <visual>
      <geometry>
        <mesh filename="package://commissioning_robot/stl/ots-barrel-display_s.stl"/>
      </geometry>
      <origin rpy="0 0 0" xyz="0 0 0"/>
      <material name="blue"/>
    </visual>
    <inertial>
      <origin rpy="0 0 0" xyz="0 0 0"/>
      <mass value="0.020168905"/>
      <inertia ixx="9.115874e-07" ixy="0.0" ixz="0.0" iyx="0.0" iyy="3.5976895e-06" iyz="0.0" izx="0.0" izy="0.0" izz="3.5976895e-06"/>
    </inertial>
    <collision>
      <origin rpy="0 0 0" xyz="0 0 0"/>
      <geometry>
        <mesh filename="package://commissioning_robot/stl/ots-barrel-display_s.stl"/>
      </geometry>
    </collision>
  </link>
  <!-- <xacro:INSERT_GAZEBO_PHYSICS_UNIT  suffix="${suffix}" mu1="${1}" mu2="${1}" kp="${2e8}" kd="${0.1}" df="${0.03}" color="Gazebo/GreyGradientSky"/> -->
  <!-- <xacro:INSERT_GAZEBO_PHYSICS_UNIT  suffix="${suffix}" mu1="${1}" mu2="${1}" kp="${1}" kd="${1}" df="${0}" color="Gazebo/GreyGradientSky"/> -->
  <gazebo reference="mechanum4_link_barrel7">
    <material>Gazebo/GreyGradientSky</material>
    <dampingFactor>0.01</dampingFactor>
  </gazebo>
  <joint name="mechanum4_link_barrel7_joint" type="continuous">
    <parent link="mechanum4_link"/>
    <child link="mechanum4_link_barrel7"/>
    <origin rpy="4.1887902047863905 0.3926990816987245 0.6801747615878314" xyz="0 -0.020145000000000017 -0.034892163518475024"/>
    <axis xyz="1 0 0"/>
    <!-- <dynamics damping="1e-4"/> -->
    <!-- <limit effort="10000" velocity="10000"/> -->
    <!-- <safety_controller k_velocity="10" k_position="15" soft_lower_limit="-2.0" soft_upper_limit="0.5" /> -->
    <!-- <safety_controller k_velocity="10" k_position="15" /> -->
    <!-- <dynamics friction="10"/> -->
  </joint>
  <transmission name="mechanum4_link_barrel7_trans">
    <type>transmission_interface/SimpleTransmission</type>
    <joint name="mechanum4_link_barrel7_joint">
      <hardwareInterface>hardware_interface/EffortJointInterface</hardwareInterface>
    </joint>
    <actuator name="mechanum4_link_barrel7_motor">
      <hardwareInterface>hardware_interface/EffortJointInterface</hardwareInterface>
      <mechanismReduction>1</mechanismReduction>
    </actuator>
  </transmission>
  <link name="mechanum4_link_barrel8">
    <visual>
      <geometry>
        <mesh filename="package://commissioning_robot/stl/ots-barrel-display_s.stl"/>
      </geometry>
      <origin rpy="0 0 0" xyz="0 0 0"/>
      <material name="blue"/>
    </visual>
    <inertial>
      <origin rpy="0 0 0" xyz="0 0 0"/>
      <mass value="0.020168905"/>
      <inertia ixx="9.115874e-07" ixy="0.0" ixz="0.0" iyx="0.0" iyy="3.5976895e-06" iyz="0.0" izx="0.0" izy="0.0" izz="3.5976895e-06"/>
    </inertial>
    <collision>
      <origin rpy="0 0 0" xyz="0 0 0"/>
      <geometry>
        <mesh filename="package://commissioning_robot/stl/ots-barrel-display_s.stl"/>
      </geometry>
    </collision>
  </link>
  <!-- <xacro:INSERT_GAZEBO_PHYSICS_UNIT  suffix="${suffix}" mu1="${1}" mu2="${1}" kp="${2e8}" kd="${0.1}" df="${0.03}" color="Gazebo/GreyGradientSky"/> -->
  <!-- <xacro:INSERT_GAZEBO_PHYSICS_UNIT  suffix="${suffix}" mu1="${1}" mu2="${1}" kp="${1}" kd="${1}" df="${0}" color="Gazebo/GreyGradientSky"/> -->
  <gazebo reference="mechanum4_link_barrel8">
    <material>Gazebo/GreyGradientSky</material>
    <dampingFactor>0.01</dampingFactor>
  </gazebo>
  <joint name="mechanum4_link_barrel8_joint" type="continuous">
    <parent link="mechanum4_link"/>
    <child link="mechanum4_link_barrel8"/>
    <origin rpy="4.886921905584122 -0.13638295981692058 0.7734662005153561" xyz="0 0.006996285078200609 -0.039677904368861865"/>
    <axis xyz="1 0 0"/>
    <!-- <dynamics damping="1e-4"/> -->
    <!-- <limit effort="10000" velocity="10000"/> -->
    <!-- <safety_controller k_velocity="10" k_position="15" soft_lower_limit="-2.0" soft_upper_limit="0.5" /> -->
    <!-- <safety_controller k_velocity="10" k_position="15" /> -->
    <!-- <dynamics friction="10"/> -->
  </joint>
  <transmission name="mechanum4_link_barrel8_trans">
    <type>transmission_interface/SimpleTransmission</type>
    <joint name="mechanum4_link_barrel8_joint">
      <hardwareInterface>hardware_interface/EffortJointInterface</hardwareInterface>
    </joint>
    <actuator name="mechanum4_link_barrel8_motor">
      <hardwareInterface>hardware_interface/EffortJointInterface</hardwareInterface>
      <mechanismReduction>1</mechanismReduction>
    </actuator>
  </transmission>
  <link name="mechanum4_link_barrel9">
    <visual>
      <geometry>
        <mesh filename="package://commissioning_robot/stl/ots-barrel-display_s.stl"/>
      </geometry>
      <origin rpy="0 0 0" xyz="0 0 0"/>
      <material name="blue"/>
    </visual>
    <inertial>
      <origin rpy="0 0 0" xyz="0 0 0"/>
      <mass value="0.020168905"/>
      <inertia ixx="9.115874e-07" ixy="0.0" ixz="0.0" iyx="0.0" iyy="3.5976895e-06" iyz="0.0" izx="0.0" izy="0.0" izz="3.5976895e-06"/>
    </inertial>
    <collision>
      <origin rpy="0 0 0" xyz="0 0 0"/>
      <geometry>
        <mesh filename="package://commissioning_robot/stl/ots-barrel-display_s.stl"/>
      </geometry>
    </collision>
  </link>
  <!-- <xacro:INSERT_GAZEBO_PHYSICS_UNIT  suffix="${suffix}" mu1="${1}" mu2="${1}" kp="${2e8}" kd="${0.1}" df="${0.03}" color="Gazebo/GreyGradientSky"/> -->
  <!-- <xacro:INSERT_GAZEBO_PHYSICS_UNIT  suffix="${suffix}" mu1="${1}" mu2="${1}" kp="${1}" kd="${1}" df="${0}" color="Gazebo/GreyGradientSky"/> -->
  <gazebo reference="mechanum4_link_barrel9">
    <material>Gazebo/GreyGradientSky</material>
    <dampingFactor>0.01</dampingFactor>
  </gazebo>
  <joint name="mechanum4_link_barrel9_joint" type="continuous">
    <parent link="mechanum4_link"/>
    <child link="mechanum4_link_barrel9"/>
    <origin rpy="5.585053606381854 -0.6016498987064662 0.504844208102444" xyz="0 0.030863930613263615 -0.02589791279427068"/>
    <axis xyz="1 0 0"/>
    <!-- <dynamics damping="1e-4"/> -->
    <!-- <limit effort="10000" velocity="10000"/> -->
    <!-- <safety_controller k_velocity="10" k_position="15" soft_lower_limit="-2.0" soft_upper_limit="0.5" /> -->
    <!-- <safety_controller k_velocity="10" k_position="15" /> -->
    <!-- <dynamics friction="10"/> -->
  </joint>
  <transmission name="mechanum4_link_barrel9_trans">
    <type>transmission_interface/SimpleTransmission</type>
    <joint name="mechanum4_link_barrel9_joint">
      <hardwareInterface>hardware_interface/EffortJointInterface</hardwareInterface>
    </joint>
    <actuator name="mechanum4_link_barrel9_motor">
      <hardwareInterface>hardware_interface/EffortJointInterface</hardwareInterface>
      <mechanismReduction>1</mechanismReduction>
    </actuator>
  </transmission>
  <!-- definition of joints -->
  <!-- robot base Joints -->
  <joint name="drive_base_joint" type="fixed">
    <parent link="base_link"/>
    <child link="drive_base_link"/>
    <origin rpy="0 0 0" xyz="0 0 0.15"/>
  </joint>
  <joint name="lift1_link_joint" type="prismatic">
    <parent link="drive_base_link"/>
    <child link="lift1_link"/>
    <origin rpy="0 0 0" xyz="0.1795 0.208 0.01"/>
    <axis xyz="0 0 1"/>
    <limit effort="10000" lower="-0.334" upper="0" velocity="1000"/>
    <dynamics damping="0"/>
  </joint>
  <transmission name="lift1_link_trans">
    <type>transmission_interface/SimpleTransmission</type>
    <joint name="lift1_link_joint">
      <hardwareInterface>hardware_interface/PositionJointInterface</hardwareInterface>
    </joint>
    <actuator name="lift1_link_motor">
      <hardwareInterface>hardware_interface/PositionJointInterface</hardwareInterface>
      <mechanismReduction>1</mechanismReduction>
    </actuator>
  </transmission>
  <joint name="lift2_link_joint" type="prismatic">
    <parent link="drive_base_link"/>
    <child link="lift2_link"/>
    <origin rpy="0 0 0" xyz="-0.1795 0.208 0.01"/>
    <axis xyz="0 0 1"/>
    <limit effort="10000" lower="-0.334" upper="0" velocity="1000"/>
    <dynamics damping="0"/>
  </joint>
  <transmission name="lift2_link_trans">
    <type>transmission_interface/SimpleTransmission</type>
    <joint name="lift2_link_joint">
      <hardwareInterface>hardware_interface/PositionJointInterface</hardwareInterface>
    </joint>
    <actuator name="lift2_link_motor">
      <hardwareInterface>hardware_interface/PositionJointInterface</hardwareInterface>
      <mechanismReduction>1</mechanismReduction>
    </actuator>
  </transmission>
  <joint name="lift3_link_joint" type="prismatic">
    <parent link="drive_base_link"/>
    <child link="lift3_link"/>
    <origin rpy="0 0 0" xyz="-0.1795 -0.208 0.01"/>
    <axis xyz="0 0 1"/>
    <limit effort="10000" lower="-0.334" upper="0" velocity="1000"/>
    <dynamics damping="0"/>
  </joint>
  <transmission name="lift3_link_trans">
    <type>transmission_interface/SimpleTransmission</type>
    <joint name="lift3_link_joint">
      <hardwareInterface>hardware_interface/PositionJointInterface</hardwareInterface>
    </joint>
    <actuator name="lift3_link_motor">
      <hardwareInterface>hardware_interface/PositionJointInterface</hardwareInterface>
      <mechanismReduction>1</mechanismReduction>
    </actuator>
  </transmission>
  <joint name="lift4_link_joint" type="prismatic">
    <parent link="drive_base_link"/>
    <child link="lift4_link"/>
    <origin rpy="0 0 0" xyz="0.1795 -0.208 0.01"/>
    <axis xyz="0 0 1"/>
    <limit effort="10000" lower="-0.334" upper="0" velocity="1000"/>
    <dynamics damping="0"/>
  </joint>
  <transmission name="lift4_link_trans">
    <type>transmission_interface/SimpleTransmission</type>
    <joint name="lift4_link_joint">
      <hardwareInterface>hardware_interface/PositionJointInterface</hardwareInterface>
    </joint>
    <actuator name="lift4_link_motor">
      <hardwareInterface>hardware_interface/PositionJointInterface</hardwareInterface>
      <mechanismReduction>1</mechanismReduction>
    </actuator>
  </transmission>
  <joint name="mechanum1_link_joint" type="continuous">
    <parent link="lift1_link"/>
    <child link="mechanum1_link"/>
    <origin rpy="0 0 0" xyz="0.0495 0.05 -0.072"/>
    <axis xyz="1 0 0"/>
    <limit effort="10000" velocity="1000"/>
    <dynamics damping="0.01"/>
  </joint>
  <transmission name="mechanum1_link_trans">
    <type>transmission_interface/SimpleTransmission</type>
    <joint name="mechanum1_link_joint">
      <hardwareInterface>hardware_interface/VelocityJointInterface</hardwareInterface>
    </joint>
    <actuator name="mechanum1_link_motor">
      <hardwareInterface>hardware_interface/VelocityJointInterface</hardwareInterface>
      <mechanismReduction>1</mechanismReduction>
    </actuator>
  </transmission>
  <joint name="mechanum2_link_joint" type="continuous">
    <parent link="lift2_link"/>
    <child link="mechanum2_link"/>
    <origin rpy="0 0 0" xyz="-0.0495 0.05 -0.072"/>
    <axis xyz="1 0 0"/>
    <limit effort="10000" velocity="1000"/>
    <dynamics damping="0.01"/>
  </joint>
  <transmission name="mechanum2_link_trans">
    <type>transmission_interface/SimpleTransmission</type>
    <joint name="mechanum2_link_joint">
      <hardwareInterface>hardware_interface/VelocityJointInterface</hardwareInterface>
    </joint>
    <actuator name="mechanum2_link_motor">
      <hardwareInterface>hardware_interface/VelocityJointInterface</hardwareInterface>
      <mechanismReduction>1</mechanismReduction>
    </actuator>
  </transmission>
  <joint name="mechanum3_link_joint" type="continuous">
    <parent link="lift3_link"/>
    <child link="mechanum3_link"/>
    <origin rpy="0 0 0" xyz="-0.0495 -0.05 -0.072"/>
    <axis xyz="1 0 0"/>
    <limit effort="10000" velocity="1000"/>
    <dynamics damping="0.01"/>
  </joint>
  <transmission name="mechanum3_link_trans">
    <type>transmission_interface/SimpleTransmission</type>
    <joint name="mechanum3_link_joint">
      <hardwareInterface>hardware_interface/VelocityJointInterface</hardwareInterface>
    </joint>
    <actuator name="mechanum3_link_motor">
      <hardwareInterface>hardware_interface/VelocityJointInterface</hardwareInterface>
      <mechanismReduction>1</mechanismReduction>
    </actuator>
  </transmission>
  <joint name="mechanum4_link_joint" type="continuous">
    <parent link="lift4_link"/>
    <child link="mechanum4_link"/>
    <origin rpy="0 0 0" xyz="0.0495 -0.05 -0.072"/>
    <axis xyz="1 0 0"/>
    <limit effort="10000" velocity="1000"/>
    <dynamics damping="0.01"/>
  </joint>
  <transmission name="mechanum4_link_trans">
    <type>transmission_interface/SimpleTransmission</type>
    <joint name="mechanum4_link_joint">
      <hardwareInterface>hardware_interface/VelocityJointInterface</hardwareInterface>
    </joint>
    <actuator name="mechanum4_link_motor">
      <hardwareInterface>hardware_interface/VelocityJointInterface</hardwareInterface>
      <mechanismReduction>1</mechanismReduction>
    </actuator>
  </transmission>
  <link name="bottom_unit_link">
    <visual>
      <geometry>
        <mesh filename="package://commissioning_robot/stl/asm-01d-under-base-frame.stl"/>
      </geometry>
      <origin rpy="0 0 0" xyz="0 0 0"/>
      <material name="red"/>
    </visual>
    <inertial>
      <origin rpy="1.5707963267948966 0 0" xyz="0 0 0"/>
      <mass value="1.9642335"/>
      <inertia ixx="0.76251439" ixy="-8.2944557e-06" ixz="-1.5541185e-07" iyx="-8.2944557e-06" iyy="0.014257043" iyz="-0.0028067188" izx="-1.5541185e-07" izy="-0.0028067188" izz="0.77600924"/>
    </inertial>
    <collision>
      <origin rpy="0 0 0" xyz="0 0 0"/>
      <geometry>
        <box size="0 0 0"/>
      </geometry>
    </collision>
  </link>
  <gazebo reference="bottom_unit_link">
    <material>Gazebo/Grey</material>
    <mu1>0</mu1>
    <mu2>0</mu2>
    <kp>10000000000000.0</kp>
    <kd>1</kd>
    <dampingFactor>0</dampingFactor>
    <!-- <minDepth>0.001</minDepth> -->
    <!-- <maxVel>0.01</maxVel> -->
    <!-- <turnGravityOff>true</turnGravityOff> -->
  </gazebo>
  <link name="second_unit_link">
    <visual>
      <geometry>
        <mesh filename="package://commissioning_robot/stl/asm-01d-second-unit.stl"/>
      </geometry>
      <origin rpy="0 0 0" xyz="0 0 0"/>
      <material name="blue"/>
    </visual>
    <inertial>
      <origin rpy="1.5707963267948966 0 0" xyz="0 0 0"/>
      <mass value="2.3949235"/>
      <inertia ixx="0.59758707" ixy="0.00020671151" ixz="-0.0022286795" iyx="0.00020671151" iyy="0.041532923" iyz="0.070790695" izx="-0.0022286795" izy="0.070790695" izz="0.61126766"/>
    </inertial>
    <collision>
      <origin rpy="0 0 0" xyz="0 0 0"/>
      <geometry>
        <box size="0 0 0"/>
      </geometry>
    </collision>
  </link>
  <gazebo reference="second_unit_link">
    <material>Gazebo/Grey</material>
    <mu1>0</mu1>
    <mu2>0</mu2>
    <kp>10000000000000.0</kp>
    <kd>1</kd>
    <dampingFactor>0</dampingFactor>
    <!-- <minDepth>0.001</minDepth> -->
    <!-- <maxVel>0.01</maxVel> -->
    <!-- <turnGravityOff>true</turnGravityOff> -->
  </gazebo>
  <link name="third_unit_link">
    <visual>
      <geometry>
        <mesh filename="package://commissioning_robot/stl/asm-01d-third-frame-unit.stl"/>
      </geometry>
      <origin rpy="0 0 0" xyz="0 0 0"/>
      <material name="green"/>
    </visual>
    <inertial>
      <origin rpy="1.5707963267948966 0 0" xyz="0 0 0"/>
      <mass value="1.6890962"/>
      <inertia ixx="0.14556756" ixy="-7.7964393e-06" ixz="1.9048102e-08" iyx="-7.7964393e-06" iyy="0.019584212" iyz="0.0054267813" izx="1.9048102e-08" izy="0.0054267813" izz="0.16329335"/>
    </inertial>
    <collision>
      <origin rpy="0 0 0" xyz="0 0 0"/>
      <geometry>
        <box size="0 0 0"/>
      </geometry>
    </collision>
  </link>
  <gazebo reference="third_unit_link">
    <material>Gazebo/Grey</material>
    <mu1>0</mu1>
    <mu2>0</mu2>
    <kp>10000000000000.0</kp>
    <kd>1</kd>
    <dampingFactor>0</dampingFactor>
    <!-- <minDepth>0.001</minDepth> -->
    <!-- <maxVel>0.01</maxVel> -->
    <!-- <turnGravityOff>true</turnGravityOff> -->
  </gazebo>
  <link name="top_unit_link">
    <visual>
      <geometry>
        <mesh filename="package://commissioning_robot/stl/asm-01d-top-base-d-frame-unit.stl"/>
      </geometry>
      <origin rpy="0 0 3.141592653589793" xyz="0 0 0"/>
      <material name="red"/>
    </visual>
    <inertial>
      <origin rpy="1.5707963267948966 0 0" xyz="0 0 0"/>
      <mass value="2.6947909"/>
      <inertia ixx="0.25680669" ixy="0.0071440461" ixz="-0.00017514047" iyx="0.0071440461" iyy="0.009114164" iyz="0.0012020167" izx="-0.00017514047" izy="0.0012020167" izz="0.26338954"/>
    </inertial>
    <collision>
      <origin rpy="0 0 3.141592653589793" xyz="0 0 0"/>
      <geometry>
        <box size="0 0 0"/>
      </geometry>
    </collision>
  </link>
  <gazebo reference="top_unit_link">
    <material>Gazebo/Grey</material>
    <mu1>0</mu1>
    <mu2>0</mu2>
    <kp>10000000000000.0</kp>
    <kd>1</kd>
    <dampingFactor>0</dampingFactor>
    <!-- <minDepth>0.001</minDepth> -->
    <!-- <maxVel>0.01</maxVel> -->
    <!-- <turnGravityOff>true</turnGravityOff> -->
  </gazebo>
  <!-- main lift link definition end -->
  <joint name="bottom_unit_link_joint" type="prismatic">
    <parent link="drive_base_link"/>
    <child link="bottom_unit_link"/>
    <origin rpy="0 0 0" xyz="0 0.06 0.03"/>
    <axis xyz="0 0 1"/>
    <limit effort="10000" lower="0" upper="0" velocity="1000"/>
    <dynamics damping="0"/>
  </joint>
  <transmission name="bottom_unit_link_trans">
    <type>transmission_interface/SimpleTransmission</type>
    <joint name="bottom_unit_link_joint">
      <hardwareInterface>hardware_interface/PositionJointInterface</hardwareInterface>
    </joint>
    <actuator name="bottom_unit_link_motor">
      <hardwareInterface>hardware_interface/PositionJointInterface</hardwareInterface>
      <mechanismReduction>1</mechanismReduction>
    </actuator>
  </transmission>
  <joint name="second_unit_link_joint" type="prismatic">
    <parent link="bottom_unit_link"/>
    <child link="second_unit_link"/>
    <origin rpy="0 0 0" xyz="0 -0.0181 0.06"/>
    <axis xyz="0 0 1"/>
    <limit effort="10000" lower="0" upper="0.68" velocity="1000"/>
    <dynamics damping="0"/>
  </joint>
  <transmission name="second_unit_link_trans">
    <type>transmission_interface/SimpleTransmission</type>
    <joint name="second_unit_link_joint">
      <hardwareInterface>hardware_interface/PositionJointInterface</hardwareInterface>
    </joint>
    <actuator name="second_unit_link_motor">
      <hardwareInterface>hardware_interface/PositionJointInterface</hardwareInterface>
      <mechanismReduction>1</mechanismReduction>
    </actuator>
  </transmission>
  <joint name="third_unit_link_joint" type="prismatic">
    <parent link="second_unit_link"/>
    <child link="third_unit_link"/>
    <origin rpy="0 0 0" xyz="0 0.1231 0.445"/>
    <axis xyz="0 0 1"/>
    <limit effort="10000" lower="0" upper="0.68" velocity="1000"/>
    <dynamics damping="0"/>
  </joint>
  <transmission name="third_unit_link_trans">
    <type>transmission_interface/SimpleTransmission</type>
    <joint name="third_unit_link_joint">
      <hardwareInterface>hardware_interface/PositionJointInterface</hardwareInterface>
    </joint>
    <actuator name="third_unit_link_motor">
      <hardwareInterface>hardware_interface/PositionJointInterface</hardwareInterface>
      <mechanismReduction>1</mechanismReduction>
    </actuator>
  </transmission>
  <joint name="top_unit_link_joint" type="prismatic">
    <parent link="third_unit_link"/>
    <child link="top_unit_link"/>
    <origin rpy="0 0 0" xyz="0 0.058 0.03"/>
    <axis xyz="0 0 1"/>
    <limit effort="10000" lower="0" upper="0.68" velocity="1000"/>
    <dynamics damping="0"/>
  </joint>
  <transmission name="top_unit_link_trans">
    <type>transmission_interface/SimpleTransmission</type>
    <joint name="top_unit_link_joint">
      <hardwareInterface>hardware_interface/PositionJointInterface</hardwareInterface>
    </joint>
    <actuator name="top_unit_link_motor">
      <hardwareInterface>hardware_interface/PositionJointInterface</hardwareInterface>
      <mechanismReduction>1</mechanismReduction>
    </actuator>
  </transmission>
  <!-- main lift joint definition end -->
</robot>

